Workbook

Sheet Date documentare
A1: Date din documentare (etapa 1) transformate în unități S.I.
A2: Se preiau datele medii din faza de documentare (suport P2/P3, slide 2). Celulele goale = valoare nedeclarată; media se face doar pe valorile existente. Rândul galben = vehiculul de referință.
A3: Text albastru = valoare preluată din sursă; text negru = formulă.
A5: Nr. | B5: Vehicul | C5: P max [kW] | D5: v max [km/h] | E5: t accel. [s] | F5: până la v [km/h] | G5: Masă [kg] | H5: Cuplu [Nm] | I5: Baterie [kWh] | J5: Autonomie min [km] | K5: Autonomie max [km] | L5: Ciclu | M5: Consum min [kWh/100 km] | N5: Consum max [kWh/100 km] | O5: Cx | P5: S [m²] | Q5: Anvelopă spate lățime [mm] | R5: Profil [%] | S5: Jantă [inch] | T5: P max [W] | U5: v max [m/s] | V5: a medie [m/s²] | W5: Baterie [Ws] | X5: Autonomie medie [km] | Y5: Consum mediu [kWh/100 km] | Z5: Consum [Ws/m] | AA5: r roată (static) [m]
A6: 1 | B6: Mercedes-AMG GT 63 4MATIC+ 4-Door Coupé | C6: 860 | D6: 300 | E6: 2.4 | F6: 100 | G6: 2460 | H6: 2000 | I6: 106 | J6: 596 | K6: 696 | L6: WLTP | M6: 17.9 | N6: 21 | O6: 0.22 | P6: 2.44 | Q6: 295 | R6: 40 | S6: 20 | T6: =C6*1000 -> 860000 | U6: =D6/3.6 -> 83.333333 | V6: =(F6/3.6)/E6 -> 11.574074 | W6: =I6*3600000 -> 381600000 | X6: =IF(COUNT(J6,K6)<2,"",AVERAGE(J6,K6)) -> 646 | Y6: =IF(COUNT(M6,N6)<2,"",AVERAGE(M6,N6)) -> 19.45 | Z6: =IF(Y6="","",Y6/100*3600) -> 700.2 | AA6: =IF(COUNT(Q6,R6,S6)<3,"",(S6*25.4/2+Q6*R6/100)/1000) -> 0.372
A7: 2 | B7: Porsche Taycan Turbo GT (Weissach) | C7: 760 | D7: 305 | E7: 2.2 | F7: 100 | G7: 2220 | H7: 1240 | I7: 97 | J7: 538 | K7: 555 | L7: WLTP | M7: 20.6 | N7: 21.3 | O7: 0.31 | P7: 2.35 | Q7: 305 | R7: 30 | S7: 21 | T7: =C7*1000 -> 760000 | U7: =D7/3.6 -> 84.722222 | V7: =(F7/3.6)/E7 -> 12.626263 | W7: =I7*3600000 -> 349200000 | X7: =IF(COUNT(J7,K7)<2,"",AVERAGE(J7,K7)) -> 546.5 | Y7: =IF(COUNT(M7,N7)<2,"",AVERAGE(M7,N7)) -> 20.95 | Z7: =IF(Y7="","",Y7/100*3600) -> 754.2 | AA7: =IF(COUNT(Q7,R7,S7)<3,"",(S7*25.4/2+Q7*R7/100)/1000) -> 0.3582
A8: 3 | B8: Audi RS e-tron GT performance | C8: 680 | D8: 250 | E8: 2.5 | F8: 100 | G8: 2320 | H8: 1027 | I8: 97 | J8: 533 | K8: 592 | L8: WLTP | M8: 18.7 | N8: 20.8 | O8: 0.26 | P8: 2.35 | Q8: 285 | R8: 40 | S8: 20 | T8: =C8*1000 -> 680000 | U8: =D8/3.6 -> 69.444444 | V8: =(F8/3.6)/E8 -> 11.111111 | W8: =I8*3600000 -> 349200000 | X8: =IF(COUNT(J8,K8)<2,"",AVERAGE(J8,K8)) -> 562.5 | Y8: =IF(COUNT(M8,N8)<2,"",AVERAGE(M8,N8)) -> 19.75 | Z8: =IF(Y8="","",Y8/100*3600) -> 711 | AA8: =IF(COUNT(Q8,R8,S8)<3,"",(S8*25.4/2+Q8*R8/100)/1000) -> 0.368
A9: 4 | B9: Lotus Emeya R | C9: 675 | D9: 256 | E9: 2.78 | F9: 100 | G9: 2565 | H9: 985 | I9: 102 | J9: 435 | K9: 485 | L9: WLTP | T9: =C9*1000 -> 675000 | U9: =D9/3.6 -> 71.111111 | V9: =(F9/3.6)/E9 -> 9.9920064 | W9: =I9*3600000 -> 367200000 | X9: =IF(COUNT(J9,K9)<2,"",AVERAGE(J9,K9)) -> 460 | Y9: =IF(COUNT(M9,N9)<2,"",AVERAGE(M9,N9)) | Z9: =IF(Y9="","",Y9/100*3600) | AA9: =IF(COUNT(Q9,R9,S9)<3,"",(S9*25.4/2+Q9*R9/100)/1000)
A10: 5 | B10: Tesla Model S Plaid | C10: 760 | D10: 322 | E10: 2.1 | F10: 100 | G10: 2178 | H10: 1420 | I10: 96 | J10: 600 | K10: 611 | L10: WLTP | M10: 18 | N10: 18.7 | O10: 0.208 | T10: =C10*1000 -> 760000 | U10: =D10/3.6 -> 89.444444 | V10: =(F10/3.6)/E10 -> 13.227513 | W10: =I10*3600000 -> 345600000 | X10: =IF(COUNT(J10,K10)<2,"",AVERAGE(J10,K10)) -> 605.5 | Y10: =IF(COUNT(M10,N10)<2,"",AVERAGE(M10,N10)) -> 18.35 | Z10: =IF(Y10="","",Y10/100*3600) -> 660.6 | AA10: =IF(COUNT(Q10,R10,S10)<3,"",(S10*25.4/2+Q10*R10/100)/1000)
A11: 6 | B11: Lucid Air Sapphire | C11: 908 | D11: 330 | E11: 1.89 | F11: 96.56 | G11: 2420 | H11: 1940 | I11: 118 | J11: 694 | K11: 694 | L11: WLTP | M11: 19.1 | N11: 19.1 | Q11: 295 | R11: 30 | S11: 21 | T11: =C11*1000 -> 908000 | U11: =D11/3.6 -> 91.666667 | V11: =(F11/3.6)/E11 -> 14.191652 | W11: =I11*3600000 -> 424800000 | X11: =IF(COUNT(J11,K11)<2,"",AVERAGE(J11,K11)) -> 694 | Y11: =IF(COUNT(M11,N11)<2,"",AVERAGE(M11,N11)) -> 19.1 | Z11: =IF(Y11="","",Y11/100*3600) -> 687.6 | AA11: =IF(COUNT(Q11,R11,S11)<3,"",(S11*25.4/2+Q11*R11/100)/1000) -> 0.3552
A12: 7 | B12: Xiaomi SU7 Ultra | C12: 1138 | D12: 350 | E12: 1.98 | F12: 100 | G12: 2360 | H12: 1770 | I12: 93.7 | J12: 555 | K12: 630 | L12: CLTC | M12: 16.5 | N12: 16.5 | T12: =C12*1000 -> 1138000 | U12: =D12/3.6 -> 97.222222 | V12: =(F12/3.6)/E12 -> 14.029181 | W12: =I12*3600000 -> 337320000 | X12: =IF(COUNT(J12,K12)<2,"",AVERAGE(J12,K12)) -> 592.5 | Y12: =IF(COUNT(M12,N12)<2,"",AVERAGE(M12,N12)) -> 16.5 | Z12: =IF(Y12="","",Y12/100*3600) -> 594 | AA12: =IF(COUNT(Q12,R12,S12)<3,"",(S12*25.4/2+Q12*R12/100)/1000)
A13: 8 | B13: Yangwang U9 | C13: 960 | D13: 309 | E13: 2.36 | F13: 100 | G13: 2475 | H13: 1680 | I13: 80 | J13: 450 | K13: 450 | L13: CLTC | T13: =C13*1000 -> 960000 | U13: =D13/3.6 -> 85.833333 | V13: =(F13/3.6)/E13 -> 11.770245 | W13: =I13*3600000 -> 288000000 | X13: =IF(COUNT(J13,K13)<2,"",AVERAGE(J13,K13)) -> 450 | Y13: =IF(COUNT(M13,N13)<2,"",AVERAGE(M13,N13)) | Z13: =IF(Y13="","",Y13/100*3600) | AA13: =IF(COUNT(Q13,R13,S13)<3,"",(S13*25.4/2+Q13*R13/100)/1000)
A14: 9 | B14: Rimac Nevera | C14: 1408 | D14: 412 | E14: 1.81 | F14: 100 | G14: 2300 | H14: 2340 | I14: 120 | J14: 489 | K14: 489 | L14: WLTP | M14: 30 | N14: 30 | O14: 0.3 | Q14: 315 | R14: 35 | S14: 20 | T14: =C14*1000 -> 1408000 | U14: =D14/3.6 -> 114.44444 | V14: =(F14/3.6)/E14 -> 15.346839 | W14: =I14*3600000 -> 432000000 | X14: =IF(COUNT(J14,K14)<2,"",AVERAGE(J14,K14)) -> 489 | Y14: =IF(COUNT(M14,N14)<2,"",AVERAGE(M14,N14)) -> 30 | Z14: =IF(Y14="","",Y14/100*3600) -> 1080 | AA14: =IF(COUNT(Q14,R14,S14)<3,"",(S14*25.4/2+Q14*R14/100)/1000) -> 0.36425
A15: 10 | B15: Maserati GranTurismo Folgore | C15: 560 | D15: 325 | E15: 2.7 | F15: 100 | G15: 2260 | H15: 1350 | I15: 83 | J15: 450 | K15: 459 | L15: WLTP | M15: 21.9 | N15: 22.3 | T15: =C15*1000 -> 560000 | U15: =D15/3.6 -> 90.277778 | V15: =(F15/3.6)/E15 -> 10.288066 | W15: =I15*3600000 -> 298800000 | X15: =IF(COUNT(J15,K15)<2,"",AVERAGE(J15,K15)) -> 454.5 | Y15: =IF(COUNT(M15,N15)<2,"",AVERAGE(M15,N15)) -> 22.1 | Z15: =IF(Y15="","",Y15/100*3600) -> 795.6 | AA15: =IF(COUNT(Q15,R15,S15)<3,"",(S15*25.4/2+Q15*R15/100)/1000)
B16: MEDIE (vehicul mediu) | C16: =AVERAGE(C6:C15) -> 870.9 | D16: =AVERAGE(D6:D15) -> 315.9 | E16: =AVERAGE(E6:E15) -> 2.272 | F16: =AVERAGE(F6:F15) -> 99.656 | G16: =AVERAGE(G6:G15) -> 2355.8 | H16: =AVERAGE(H6:H15) -> 1575.2 | I16: =AVERAGE(I6:I15) -> 99.27 | J16: =AVERAGEIF(L6:L15,"WLTP",J6:J15) -> 541.875 | K16: =AVERAGEIF(L6:L15,"WLTP",K6:K15) -> 572.625 | M16: =AVERAGEIF(L6:L15,"WLTP",M6:M15) -> 20.885714 | N16: =AVERAGEIF(L6:L15,"WLTP",N6:N15) -> 21.885714 | O16: =AVERAGE(O6:O15) -> 0.2596 | P16: =AVERAGE(P6:P15) -> 2.38 | Q16: =AVERAGE(Q6:Q15) -> 299 | R16: =AVERAGE(R6:R15) -> 35 | S16: =AVERAGE(S6:S15) -> 20.4 | T16: =AVERAGE(T6:T15) -> 870900 | U16: =AVERAGE(U6:U15) -> 87.75 | V16: =AVERAGE(V6:V15) -> 12.415695 | W16: =AVERAGE(W6:W15) -> 357372000 | X16: =AVERAGEIF(L6:L15,"WLTP",X6:X15) -> 557.25 | Y16: =AVERAGEIF(L6:L15,"WLTP",Y6:Y15) -> 21.385714 | Z16: =AVERAGEIF(L6:L15,"WLTP",Z6:Z15) -> 769.88571 | AA16: =AVERAGE(AA6:AA15) -> 0.36353
B17: Număr de valori | C17: =COUNT(C6:C15) -> 10 | D17: =COUNT(D6:D15) -> 10 | E17: =COUNT(E6:E15) -> 10 | F17: =COUNT(F6:F15) -> 10 | G17: =COUNT(G6:G15) -> 10 | H17: =COUNT(H6:H15) -> 10 | I17: =COUNT(I6:I15) -> 10 | J17: =COUNTIFS(L6:L15,"WLTP",J6:J15,">=0") -> 8 | K17: =COUNTIFS(L6:L15,"WLTP",K6:K15,">=0") -> 8 | M17: =COUNTIFS(L6:L15,"WLTP",M6:M15,">=0") -> 7 | N17: =COUNTIFS(L6:L15,"WLTP",N6:N15,">=0") -> 7 | O17: =COUNT(O6:O15) -> 5 | P17: =COUNT(P6:P15) -> 3 | Q17: =COUNT(Q6:Q15) -> 5 | R17: =COUNT(R6:R15) -> 5 | S17: =COUNT(S6:S15) -> 5 | T17: =COUNT(T6:T15) -> 10 | U17: =COUNT(U6:U15) -> 10 | V17: =COUNT(V6:V15) -> 10 | W17: =COUNT(W6:W15) -> 10 | X17: =COUNTIFS(L6:L15,"WLTP",X6:X15,">=0") -> 8 | Y17: =COUNTIFS(L6:L15,"WLTP",Y6:Y15,">=0") -> 7 | Z17: =COUNTIFS(L6:L15,"WLTP",Z6:Z15,">=0") -> 7 | AA17: =COUNT(AA6:AA15) -> 5
B19: Note: Lucid Air Sapphire – 1,89 s este 0–60 mph (96,56 km/h). Rimac (și, după convenția americană, Tesla și Lucid) declară timpi cu „1-foot rollout”; GT 63: valoarea standard 2,4 s. Autonomia și consumul se mediază doar pe valorile WLTP (Xiaomi și Yangwang declară ciclul chinezesc CLTC, mai optimist). Lotus nu publică un consum WLTP separat pentru Emeya R. Tesla și Maserati: autonomie și consum din EV Database (sursă secundară). Raza roții se calculează din anvelopa punții spate: r = D_jantă/2 + lățime·profil.

Sheet Sinteză
A1: Sinteză – date pentru proiectare (tema de proiectare)
A2: Valorile provin din foile P2, P3 și Baterie. Vehiculul mediu este baza temei; GT 63 este comparația.
A4: Subsistem | B4: Mărime | C4: Unitate | D4: Vehicul mediu | E4: GT 63 (referință)
A5: Mașina electrică | B5: Tipul mașinii | C5: - | D5: ="MCA – sincronă cu magneți permanenți" -> MCA – sincronă cu magneți permanenți | E5: ="MCA – sincronă cu magneți permanenți" -> MCA – sincronă cu magneți permanenți
B6: Puterea maximă (vârf) | C6: kW | D6: ='P2 Putere'!E51 -> 518.75192 | E6: ='P2 Putere'!F51 -> 541.69697
B7: Puterea nominală (la Vmax constantă) | C7: kW | D7: ='P2 Putere'!E52 -> 299.24863 | E7: ='P2 Putere'!F52 -> 229.27038
B8: Cuplul maxim la ax | C8: Nm | D8: ='P2 Putere'!E40 -> 1043.2526 | E8: ='P2 Putere'!F40 -> 1034.565
B9: Turația de bază | C9: rot/min | D9: ='P2 Putere'!E39 -> 4748.3381 | E9: ='P2 Putere'!F39 -> 5000
B10: Turația maximă | C10: rot/min | D10: =c_n_max -> 15000 | E10: =c_n_max -> 15000
A11: Reductor | B11: i_rd = Ωr/Ωax | C11: - | D11: ='P2 Putere'!E36 -> 0.15960967 | E11: ='P2 Putere'!F36 -> 0.15157614
B12: 1/i_rd = n_motor/n_roată | C12: - | D12: ='P2 Putere'!E37 -> 6.2652845 | E12: ='P2 Putere'!F37 -> 6.5973446
A13: Vehicul | B13: Accelerația realizabilă (aderență) | C13: m/s² | D13: ='P2 Putere'!E24 -> 7.5896402 | E13: ='P2 Putere'!F24 -> 7.6116169
B14: Timpul 0–100 km/h realizabil | C14: s | D14: ='P2 Putere'!E26 -> 3.6599598 | E14: ='P2 Putere'!F26 -> 3.6493925
A15: Sistem de stocare | B15: Energia necesară în baterie | C15: kWh | D15: ='P3 Energie'!E54 -> 104.37936 | E15: ='P3 Energie'!F54 -> 122.01853
B16: Consumul echivalent al ciclului P3 | C16: kWh/100 km | D16: ='P3 Energie'!E56 -> 13.111809 | E16: ='P3 Energie'!F56 -> 13.221822
B17: Celule (serie × paralel = total) | C17: - | D17: =TEXT(Baterie!E12,"0")&"s × "&TEXT(Baterie!E21,"0")&"p = "&TEXT(Baterie!E22,"0") -> 202s × 29p = 5858 | E17: =TEXT(Baterie!F12,"0")&"s × "&TEXT(Baterie!F21,"0")&"p = "&TEXT(Baterie!F22,"0") -> 202s × 34p = 6868
B18: Energia instalată | C18: kWh | D18: =Baterie!E23 -> 105.444 | E18: =Baterie!F23 -> 123.624
B19: Tensiunea nominală (min – max) | C19: V | D19: =TEXT(Baterie!E13,"0")&" ("&TEXT(Baterie!E15,"0")&" – "&TEXT(Baterie!E14,"0")&")" -> 727 (505 – 848) | E19: =TEXT(Baterie!F13,"0")&" ("&TEXT(Baterie!F15,"0")&" – "&TEXT(Baterie!F14,"0")&")" -> 727 (505 – 848)
B20: Masa celulelor / pachetului (estimare) | C20: kg | D20: =TEXT(Baterie!E31,"0")&" / "&TEXT(Baterie!E32,"0") -> 416 / 660 | E20: =TEXT(Baterie!F31,"0")&" / "&TEXT(Baterie!F32,"0") -> 488 / 774
A21: Convertor / invertor | B21: Tip | C21: - | D21: ="invertor trifazat (DC-AC)" -> invertor trifazat (DC-AC) | E21: ="invertor trifazat (DC-AC)" -> invertor trifazat (DC-AC)
B22: Curentul bateriei la U_nom / U_min | C22: A | D22: =TEXT(Baterie!E18,"0")&" / "&TEXT(Baterie!E19,"0") -> 892 / 1284 | E22: =TEXT(Baterie!F18,"0")&" / "&TEXT(Baterie!F19,"0") -> 931 / 1341

Sheet Ipoteze
A1: Ipoteze și constante de calcul
A2: Valorile scrise cu albastru (coloana C) se pot modifica; toate foile de calcul folosesc numele definite din coloana A.
A4: Nume definit | B4: Mărime | C4: Valoare | D4: Unitate | E4: Justificare / sursă
A5: c_g | B5: Accelerația gravitațională g | C5: 9.81 | D5: m/s² | E5: Valoare uzuală (g_n = 9,80665 m/s²)
A6: c_rho | B6: Densitatea aerului ρ (condiții normale: 0 °C, 101 325 Pa) | C6: 1.293 | D6: kg/m³ | E6: ρ = p/(R_s·T) = 101325/(287,05·273,15)
A7: c_mu_f | B7: Coeficient de frecare la rulare µf | C7: 0.013 | D7: - | E7: Exemplul din curs (P2, slide 5); f = 0,01·(1 + V/160) dă 0,013 la 50 km/h (Ehsani)
A8: c_mu_a | B8: Coeficient de aderență µa | C8: 0.8 | D8: - | E8: Exemplul din curs (P2, slide 5); asfalt uscat la ≈ 90 km/h; anvelope bune: 1,0–1,2
A9: c_alpha | B9: Unghiul de înclinare al drumului α | C9: 0 | D9: rad | E9: Drum drept (simplificare curs)
A10: c_Vv | B10: Viteza vântului Vv | C10: 0 | D10: m/s | E10: Fără vânt (simplificare curs)
A11: c_r | B11: Raza dinamică a roții r | C11: 0.35 | D11: m | E11: Media razelor anvelopelor spate ≈ 0,364 m × 0,97 ≈ 0,35 m
A12: c_pp | B12: Pierderi în reductor Pp / Pax | C12: 0.01 | D12: - | E12: Pp = Pax/100 (curs, P2 slide 7)
A13: c_Va_kmh | B13: Viteza Va (punct pe rampa de accelerare) | C13: 100 | D13: km/h | E13: Sfârșitul probei 0–100 km/h
A14: c_n_max | B14: Turația maximă a mașinii electrice la v_max | C14: 15000 | D14: rot/min | E14: Alegere de proiectare (motoarele clasei: GT 63 spate > 13 000 / față > 15 000 rot/min; Xiaomi V8s 27 200 rot/min)
A15: c_V1_kmh | B15: Viteza constantă a ciclului P3, V1 | C15: 50 | D15: km/h | E15: Curs, P3 slide 4
A16: c_eta | B16: Randament η_el-mec = η_mec-el | C16: 0.8 | D16: - | E16: Curs, P3 slide 8 (pierderi tipice ale acționării 15–20 %)
... A19: c_k_masa | B19: Masa maximă a bateriei / masa vehiculului | C19: 0.3 | D19: - | E19: Curs, P3 slide 9
B21: Celula Li-ion aleasă: Molicel INR-21700-P50B | E21: https://www.molicel.com/wp-content/uploads/4.TR%E7%B0%A1%E6%98%93%E8%A6%8F%E6%A0%BC_INR21700P50B_1.1_Product-Data-Sheet-of-INR-21700-P50B-80122.pdf
A22: cel_U_nom | B22: Tensiune nominală celulă | C22: 3.6 | D22: V | E22: Fișa tehnică Molicel P50B v1.1
A23: cel_U_max | B23: Tensiune maximă (încărcare) | C23: 4.2 | D23: V | E23: Tensiunea de încărcare
A24: cel_U_min | B24: Tensiune minimă (descărcare) | C24: 2.5 | D24: V | E24: Tensiunea de descărcare (cut-off)
A25: cel_Cap | B25: Capacitate nominală | C25: 5 | D25: Ah | E25: Capacitate tipică 5000 mAh (minimă 4850 mAh); 18,0 Wh
A26: cel_m | B26: Masă celulă | C26: 0.071 | D26: kg | E26: Masă maximă 71 g (18,0 Wh / 0,071 kg ≈ 254 Wh/kg)
A27: cel_I | B27: Curent maxim de descărcare continuă | C27: 60 | D27: A | E27: Descărcare continuă 60 A (cu limită de temperatură 80 °C)
A28: cel_kcp | B28: Raport masă celule / masă pachet | C28: 0.63 | D28: - | E28: Mediana pachetelor NMC (Koloch et al., World Electr. Veh. J. 16:484, 2025); intervalul tipic pentru celule cilindrice: 0,55–0,70

Sheet P2 Putere
A1: P2 – Calculul puterii mașinii electrice (pașii 1–9)
A2: Strategie: se pleacă de la forțele rezistente pe vehicul: Ft → Mr → Pr → Pax. Simplificări: α = 0, Vv = 0, deplasare în linie dreaptă (Vr = V).
A4: Pas | B4: Mărime | C4: Simbol | D4: Unitate | E4: Vehicul mediu | F4: GT 63 (referință) | G4: Formulă / observație
A5: Date de intrare (din documentare, S.I.)
B6: Masa vehiculului | C6: M | D6: kg | E6: ='Date documentare'!G16 -> 2355.8 | F6: ='Date documentare'!G6 -> 2460 | G6: medie / rândul GT 63
B7: Coeficient aerodinamic | C7: Cx | D7: - | E7: ='Date documentare'!O16 -> 0.2596 | F7: ='Date documentare'!O6 -> 0.22
B8: Suprafața frontală | C8: S | D8: m² | E8: ='Date documentare'!P16 -> 2.38 | F8: ='Date documentare'!P6 -> 2.44
B9: Viteza maximă | C9: Vmax | D9: m/s | E9: ='Date documentare'!U16 -> 87.75 | F9: ='Date documentare'!U6 -> 83.333333
B10: Accelerația medie 0–100 km/h (documentare) | C10: a_doc | D10: m/s² | E10: ='Date documentare'!V16 -> 12.415695 | F10: ='Date documentare'!V6 -> 11.574074
B11: Puterea maximă declarată | C11: P_doc | D11: W | E11: ='Date documentare'!T16 -> 870900 | F11: ='Date documentare'!T6 -> 860000
B12: Raza roții | C12: r | D12: m | E12: =c_r -> 0.35 | F12: =c_r -> 0.35 | G12: Ipoteze
A13: Pașii 1–4: forța de tracțiune în punctul (Va, ta) și aderența
A14: 1–2 | B14: Viteza Va (punct pe rampa de accelerare) | C14: Va | D14: m/s | E14: =c_Va_kmh/3.6 -> 27.777778 | F14: =c_Va_kmh/3.6 -> 27.777778 | G14: Va = 100 km/h (sfârșitul probei 0–100 km/h)
A15: 2 | B15: Timpul de accelerare (documentare) | C15: ta | D15: s | E15: =E14/E10 -> 2.2373116 | F15: =F14/F10 -> 2.4 | G15: ta = Va / a
A16: 3 | B16: Forța de frecare la rulare | C16: Ff | D16: N | E16: =c_mu_f*E6*c_g*COS(c_alpha) -> 300.43517 | F16: =c_mu_f*F6*c_g*COS(c_alpha) -> 313.7238 | G16: Ff = µf·M·g·cos α
A17: 3 | B17: Rezistența aerodinamică la Va | C17: Fra | D17: N | E17: =0.5*c_rho*E8*E7*(E14-c_Vv)^2 -> 308.2089 | F17: =0.5*c_rho*F8*F7*(F14-c_Vv)^2 -> 267.7787 | G17: Fra = ½·ρ·S·Cx·(V − Vv)²
A18: 3 | B18: Componenta tangențială a greutății | C18: Gt | D18: N | E18: =E6*c_g*SIN(c_alpha) -> 0 | F18: =F6*c_g*SIN(c_alpha) -> 0 | G18: Gt = M·g·sin α
A19: 3 | B19: Forța de inerție cu a_doc | C19: M·a | D19: N | E19: =E6*E10 -> 29248.894 | F19: =F6*F10 -> 28472.222
A20: 3 | B20: Forța de tracțiune necesară | C20: Ft | D20: N | E20: =E17+E16+E18+E19 -> 29857.538 | F20: =F17+F16+F18+F19 -> 29053.725 | G20: Ft = Fra + Ff + Gt + M·a
A21: 4 | B21: Forța de aderență | C21: Fa | D21: N | E21: =c_mu_a*E6*c_g*COS(c_alpha) -> 18488.318 | F21: =c_mu_a*F6*c_g*COS(c_alpha) -> 19306.08 | G21: Fa = µa·M·g·cos α
A22: 4 | B22: Coeficientul de aderență necesar pentru a_doc | C22: µ_nec | D22: - | E22: =E20/(E6*c_g*COS(c_alpha)) -> 1.2919526 | F22: =F20/(F6*c_g*COS(c_alpha)) -> 1.2039202 | G22: µ_nec = Ft / (M·g·cos α)
A23: 4 | B23: Aderența respectată? (Ft ≤ Fa) | E23: =IF(E20<=E21,"DA","NU") -> NU | F23: =IF(F20<=F21,"DA","NU") -> NU | G23: Dacă NU: Ft = Fa și se recalculează accelerația
A24: 4 | B24: Accelerația realizabilă | C24: a | D24: m/s² | E24: =IF(E20<=E21,E10,(E21-E17-E16-E18)/E6) -> 7.5896402 | F24: =IF(F20<=F21,F10,(F21-F17-F16-F18)/F6) -> 7.6116169 | G24: a = (Fa − Fra − Ff − Gt)/M
A25: 4 | B25: Forța de tracțiune de calcul | C25: Ft | D25: N | E25: =IF(E20<=E21,E20,E21) -> 18488.318 | F25: =IF(F20<=F21,F20,F21) -> 19306.08
A26: 4 | B26: Timpul 0–100 km/h realizabil | C26: ta | D26: s | E26: =E14/E24 -> 3.6599598 | F26: =F14/F24 -> 3.6493925
A27: Pasul 5: cuplul și puterea la roată; puterea la axul mașinii
A28: 5 | B28: Viteza unghiulară a roții la Va | C28: Ωr | D28: rad/s | E28: =E14/E12 -> 79.365079 | F28: =F14/F12 -> 79.365079 | G28: Ωr = Va / r
A29: 5 | B29: Cuplul la roată (total) | C29: Mr | D29: Nm | E29: =E12*E25 -> 6470.9114 | F29: =F12*F25 -> 6757.128 | G29: Mr = r·Ft
A30: 5 | B30: Puterea la roată | C30: Pr | D30: W | E30: =E29*E28 -> 513564.4 | F30: =F29*F28 -> 536280 | G30: Pr = Mr·Ωr = Ft·Vr
A31: 5 | B31: Puterea la axul mașinii electrice | C31: Pax | D31: W | E31: =E30/(1-c_pp) -> 518751.92 | F31: =F30/(1-c_pp) -> 541696.97 | G31: Pax = Pr + Pp, Pp = Pax/100 ⇒ Pax = Pr/0,99
A32: 5 | B32: Pierderi în reductor și transmisie | C32: Pp | D32: W | E32: =E31-E30 -> 5187.5192 | F32: =F31-F30 -> 5416.9697
A33: Pasul 6: reductorul și cuplul la axul mașinii
A34: 6 | B34: Viteza unghiulară a roții la Vmax | C34: Ωr,max | D34: rad/s | E34: =E9/E12 -> 250.71429 | F34: =F9/F12 -> 238.09524
A35: 6 | B35: Viteza unghiulară maximă a mașinii | C35: Ωax,max | D35: rad/s | E35: =c_n_max*2*PI()/60 -> 1570.7963 | F35: =c_n_max*2*PI()/60 -> 1570.7963 | G35: din n_max ales (Ipoteze)
A36: 6 | B36: Raportul reductorului | C36: i_rd | D36: - | E36: =E34/E35 -> 0.15960967 | F36: =F34/F35 -> 0.15157614 | G36: i_rd = Ωr / Ωax
A37: 6 | B37: Raport de reducere (n_motor / n_roată) | C37: 1/i_rd | D37: - | E37: =1/E36 -> 6.2652845 | F37: =1/F36 -> 6.5973446
A38: 6 | B38: Viteza unghiulară a mașinii la Va (de bază) | C38: Ωax | D38: rad/s | E38: =E28/E36 -> 497.2448 | F38: =F28/F36 -> 523.59878
A39: 6 | B39: Turația de bază a mașinii | C39: n_b | D39: rot/min | E39: =E38*60/(2*PI()) -> 4748.3381 | F39: =F38*60/(2*PI()) -> 5000
A40: 6 | B40: Cuplul maxim la axul mașinii | C40: Max | D40: Nm | E40: =E31/E38 -> 1043.2526 | F40: =F31/F38 -> 1034.565 | G40: Max = Pax / Ωax
A41: Pașii 7–9: rulare cu Vmax constantă (a = 0) – puterea nominală
...

Sheet P3 Energie
A1: P3 – Necesarul de energie electrică (pașii 1–14)
A2: Ciclu: accelerare cu a până la V1 = 50 km/h, rulare cu V1 constantă, decelerare (df = d1). Distanța totală a ciclului = autonomia medie din documentare.
A4: Pas | B4: Mărime | C4: Simbol | D4: Unitate | E4: Vehicul mediu | F4: GT 63 (referință) | G4: Formulă / observație
A5: Date de intrare
B6: Masa vehiculului | C6: M | D6: kg | E6: ='Date documentare'!G16 -> 2355.8 | F6: ='Date documentare'!G6 -> 2460
B7: Coeficient aerodinamic | C7: Cx | D7: - | E7: ='Date documentare'!O16 -> 0.2596 | F7: ='Date documentare'!O6 -> 0.22
B8: Suprafața frontală | C8: S | D8: m² | E8: ='Date documentare'!P16 -> 2.38 | F8: ='Date documentare'!P6 -> 2.44
B9: Cerința de autonomie | C9: d | D9: m | E9: ='Date documentare'!X16*1000 -> 557250 | F9: ='Date documentare'!X6*1000 -> 646000 | G9: media din documentare
A10: 2 | B10: Accelerația din sesiunea precedentă (P2: a = Va/ta) | C10: a | D10: m/s² | E10: ='P2 Putere'!E10 -> 12.415695 | F10: ='P2 Putere'!F10 -> 11.574074 | G10: sesiunea precedentă (P2, pasul 4)
A11: Pașii 1–6: puterea P1 (cu a), P1' (fără a), timpul t1
A12: 1 | B12: Viteza constantă a ciclului | C12: V1 | D12: m/s | E12: =c_V1_kmh/3.6 -> 13.888889 | F12: =c_V1_kmh/3.6 -> 13.888889 | G12: V1 = 50 km/h
A13: 3 | B13: Forța de frecare la rulare | C13: Ff | D13: N | E13: =c_mu_f*E6*c_g*COS(c_alpha) -> 300.43517 | F13: =c_mu_f*F6*c_g*COS(c_alpha) -> 313.7238
A14: 3 | B14: Rezistența aerodinamică la V1 | C14: Fra | D14: N | E14: =0.5*c_rho*E8*E7*(E12-c_Vv)^2 -> 77.052225 | F14: =0.5*c_rho*F8*F7*(F12-c_Vv)^2 -> 66.944676
A15: 3 | B15: Componenta tangențială a greutății | C15: Gt | D15: N | E15: =E6*c_g*SIN(c_alpha) -> 0 | F15: =F6*c_g*SIN(c_alpha) -> 0
A16: 4 | B16: Forța de aderență | C16: Fa | D16: N | E16: =c_mu_a*E6*c_g*COS(c_alpha) -> 18488.318 | F16: =c_mu_a*F6*c_g*COS(c_alpha) -> 19306.08
A17: 3 | B17: Ft1 cu accelerația din P2 | C17: Ft1 | D17: N | E17: =E14+E13+E15+E6*E10 -> 29626.382 | F17: =F14+F13+F15+F6*F10 -> 28852.891
A18: 4 | B18: Aderența respectată? (Ft1 ≤ Fa) | E18: =IF(E17<=E16,"DA","NU") -> NU | F18: =IF(F17<=F16,"DA","NU") -> NU
A19: 4 | B19: Accelerația folosită | C19: a | D19: m/s² | E19: =IF(E17<=E16,E10,(E16-E14-E13-E15)/E6) -> 7.6877625 | F19: =IF(F17<=F16,F10,(F16-F14-F13-F15)/F6) -> 7.6932567
A20: 3 | B20: Forța de tracțiune în (V1, t1) | C20: Ft1 | D20: N | E20: =E14+E13+E15+E6*E19 -> 18488.318 | F20: =F14+F13+F15+F6*F19 -> 19306.08 | G20: Ft1 = Fra + Ff + Gt + M·a
A21: 3 | B21: Puterea P1 (cu accelerație) | C21: P1 | D21: W | E21: =E20*E12 -> 256782.2 | F21: =F20*F12 -> 268140 | G21: P1 = Ft1·V1
A22: 5 | B22: Forța de tracțiune la V1 constantă | C22: Ft1' | D22: N | E22: =E14+E13+E15 -> 377.4874 | F22: =F14+F13+F15 -> 380.66848 | G22: Ft1' = Fra + Ff + Gt
A23: 5 | B23: Puterea P1' (fără accelerație) | C23: P1' | D23: W | E23: =E22*E12 -> 5242.8805 | F23: =F22*F12 -> 5287.0622 | G23: P1' = Ft1'·V1
A24: 6 | B24: Timpul de accelerare până la V1 | C24: t1 | D24: s | E24: =E12/E19 -> 1.806623 | F24: =F12/F19 -> 1.8053328 | G24: t1 = V1 / a
A25: Pașii 7–8: puterea medie și energia pe [0, t1]
A26: 7 | B26: Puterea medie (aproximare) | C26: Pmed | D26: W | E26: =(0+E21)/2 -> 128391.1 | F26: =(0+F21)/2 -> 134070 | G26: Pmed = (P0 + P1)/2, P0 = 0
A27: 7 | B27: Puterea medie discretizată, n = 100 | C27: P01-med | D27: W | E27: ='P3 n=100'!C4 -> 126839.67 | F27: ='P3 n=100'!H4 -> 132496.88 | G27: (1/n)·Σ(i=1..n) Fti·Vti – începutul intervalelor (foaia P3 n=100)
A28: 8 | B28: Energia W01-med, n = 100 | C28: W01-med | D28: Ws | E28: =E27*E24 -> 229151.48 | F28: =F27*F24 -> 239200.96 | G28: W01-med = P01-med·t1
A29: 8 | B29: Energia W01 discretizată, n = 100 | C29: W01 | D29: Ws | E29: ='P3 n=100'!C5 -> 233790.56 | F29: ='P3 n=100'!H5 -> 244041.78 | G29: Σ(i=1..n+1) Pti·Δti – sfârșitul intervalelor (P(0) = 0)
A30: 7 | B30: Puterea medie discretizată, n = 1000 | C30: P01-med | D30: W | E30: ='P3 n=1000'!C4 -> 127995.17 | F30: ='P3 n=1000'!H4 -> 133703.48 | G30: (1/n)·Σ(i=1..n) Fti·Vti – începutul intervalelor (foaia P3 n=1000)
A31: 8 | B31: Energia W01-med, n = 1000 | C31: W01-med | D31: Ws | E31: =E30*E24 -> 231239.02 | F31: =F30*F24 -> 241379.29 | G31: W01-med = P01-med·t1
A32: 8 | B32: Energia W01 discretizată, n = 1000 | C32: W01 | D32: Ws | E32: ='P3 n=1000'!C5 -> 231702.93 | F32: ='P3 n=1000'!H5 -> 241863.37 | G32: Σ(i=1..n+1) Pti·Δti – sfârșitul intervalelor (P(0) = 0)
A33: 8 | B33: Energia W01 exactă (integrală analitică) | C33: W01 | D33: Ws | E33: =(E13+E15+E6*E19)*E19*E24^2/2+0.5*c_rho*E8*E7*E19^3*E24^4/4 -> 231470.97 | F33: =(F13+F15+F6*F19)*F19*F24^2/2+0.5*c_rho*F8*F7*F19^3*F24^4/4 -> 241621.33 | G33: ∫(A + B·v²)·v dt, v = a·t (Vv = 0)
A34: 8 | B34: Eroarea W01-med pentru n = 100 | D34: % | E34: =(E28-E33)/E33*100 -> -1.0020673 | F34: =(F28-F33)/F33*100 -> -1.0017194 | G34: subestimare
A35: 8 | B35: Eroarea W01 pentru n = 100 | D35: % | E35: =(E29-E33)/E33*100 -> 1.002109 | F35: =(F29-F33)/F33*100 -> 1.0017542 | G35: supraestimare
A36: 8 | B36: Eroarea W01-med pentru n = 1000 | D36: % | E36: =(E31-E33)/E33*100 -> -0.10020861 | F36: =(F31-F33)/F33*100 -> -0.1001735 | G36: subestimare
A37: 8 | B37: Eroarea W01 pentru n = 1000 | D37: % | E37: =(E32-E33)/E33*100 -> 0.10020902 | F37: =(F32-F33)/F33*100 -> 0.10017385 | G37: supraestimare
A38: 8 | B38: Energia cu puterea medie | C38: Wmed | D38: Ws | E38: =E26*E24 -> 231954.32 | F38: =F26*F24 -> 242040.97 | G38: Wmed = Pmed·t1
A39: 8 | B39: Energia W01-med folosită la comparație (n = 1000) | C39: W01-med | D39: Ws | E39: =E31 -> 231239.02 | F39: =F31 -> 241379.29
A40: 8 | B40: Energia W01 folosită mai departe (n = 1000) | C40: W01 | D40: Ws | E40: =E32 -> 231702.93 | F40: =F32 -> 241863.37
A41: Pașii 9–12: distanțe și energia mecanică pe ciclu
...

Sheet P3 n=100
A1: P3 – discretizarea intervalului [0, t1] în n = 100 intervale egale
A2: Indicii ca în curs (și în Matlab): i = 1 … n+1, t_i = (i − 1)·Δt. P01-med = (1/n)·Σ(i=1..n) Fti·Vti folosește valorile de la începutul intervalelor; W01 = Σ(i=1..n+1) Pti·Δt, cu P(t_1) = 0, folosește valorile de la sfârșitul intervalelor. Cele două sume încadrează valoarea exactă.
A3: Vehicul mediu | F3: GT 63
B4: P01-med [W] | C4: =SUM(E9:E108)/100 -> 126839.67 | G4: P01-med [W] | H4: =SUM(J9:J108)/100 -> 132496.88
B5: W01 [Ws] | C5: =SUM(E9:E109)*C6 -> 233790.56 | G5: W01 [Ws] | H5: =SUM(J9:J109)*H6 -> 244041.78
B6: Δt [s] | C6: ='P3 Energie'!E24/100 -> 0.01806623 | G6: Δt [s] | H6: ='P3 Energie'!F24/100 -> 0.018053328
B7: a [m/s²] | C7: ='P3 Energie'!E19 -> 7.6877625 | G7: a [m/s²] | H7: ='P3 Energie'!F19 -> 7.6932567
A8: i | B8: t_i [s] | C8: V_ti [m/s] | D8: F_ti [N] | E8: P_ti [W] | F8: i | G8: t_i [s] | H8: V_ti [m/s] | I8: F_ti [N] | J8: P_ti [W]
A9: 1 | B9: =(A9-1)*$C$6 -> 0 | C9: =$C$7*B9 -> 0 | D9: =0.5*c_rho*'P3 Energie'!E8*'P3 Energie'!E7*(C9-c_Vv)^2+'P3 Energie'!E13+'P3 Energie'!E15+'P3 Energie'!E6*$C$7 -> 18411.266 | E9: =D9*C9 -> 0 | F9: 1 | G9: =(F9-1)*$H$6 -> 0 | H9: =$H$7*G9 -> 0 | I9: =0.5*c_rho*'P3 Energie'!F8*'P3 Energie'!F7*(H9-c_Vv)^2+'P3 Energie'!F13+'P3 Energie'!F15+'P3 Energie'!F6*$H$7 -> 19239.135 | J9: =I9*H9 -> 0
A10: 2 | B10: =(A10-1)*$C$6 -> 0.01806623 | C10: =$C$7*B10 -> 0.13888889 | D10: =0.5*c_rho*'P3 Energie'!E8*'P3 Energie'!E7*(C10-c_Vv)^2+'P3 Energie'!E13+'P3 Energie'!E15+'P3 Energie'!E6*$C$7 -> 18411.274 | E10: =D10*C10 -> 2557.1214 | F10: 2 | G10: =(F10-1)*$H$6 -> 0.018053328 | H10: =$H$7*G10 -> 0.13888889 | I10: =0.5*c_rho*'P3 Energie'!F8*'P3 Energie'!F7*(H10-c_Vv)^2+'P3 Energie'!F13+'P3 Energie'!F15+'P3 Energie'!F6*$H$7 -> 19239.142 | J10: =I10*H10 -> 2672.1031
A11: 3 | B11: =(A11-1)*$C$6 -> 0.036132461 | C11: =$C$7*B11 -> 0.27777778 | D11: =0.5*c_rho*'P3 Energie'!E8*'P3 Energie'!E7*(C11-c_Vv)^2+'P3 Energie'!E13+'P3 Energie'!E15+'P3 Energie'!E6*$C$7 -> 18411.297 | E11: =D11*C11 -> 5114.2492 | F11: 3 | G11: =(F11-1)*$H$6 -> 0.036106657 | H11: =$H$7*G11 -> 0.27777778 | I11: =0.5*c_rho*'P3 Energie'!F8*'P3 Energie'!F7*(H11-c_Vv)^2+'P3 Energie'!F13+'P3 Energie'!F15+'P3 Energie'!F6*$H$7 -> 19239.162 | J11: =I11*H11 -> 5344.2117
A12: 4 | B12: =(A12-1)*$C$6 -> 0.054198691 | C12: =$C$7*B12 -> 0.41666667 | D12: =0.5*c_rho*'P3 Energie'!E8*'P3 Energie'!E7*(C12-c_Vv)^2+'P3 Energie'!E13+'P3 Energie'!E15+'P3 Energie'!E6*$C$7 -> 18411.336 | E12: =D12*C12 -> 7671.3898 | F12: 4 | G12: =(F12-1)*$H$6 -> 0.054159985 | H12: =$H$7*G12 -> 0.41666667 | I12: =0.5*c_rho*'P3 Energie'!F8*'P3 Energie'!F7*(H12-c_Vv)^2+'P3 Energie'!F13+'P3 Energie'!F15+'P3 Energie'!F6*$H$7 -> 19239.196 | J12: =I12*H12 -> 8016.3315
A13: 5 | B13: =(A13-1)*$C$6 -> 0.072264921 | C13: =$C$7*B13 -> 0.55555556 | D13: =0.5*c_rho*'P3 Energie'!E8*'P3 Energie'!E7*(C13-c_Vv)^2+'P3 Energie'!E13+'P3 Energie'!E15+'P3 Energie'!E6*$C$7 -> 18411.389 | E13: =D13*C13 -> 10228.55 | F13: 5 | G13: =(F13-1)*$H$6 -> 0.072213313 | H13: =$H$7*G13 -> 0.55555556 | I13: =0.5*c_rho*'P3 Energie'!F8*'P3 Energie'!F7*(H13-c_Vv)^2+'P3 Energie'!F13+'P3 Energie'!F15+'P3 Energie'!F6*$H$7 -> 19239.242 | J13: =I13*H13 -> 10688.468
A14: 6 | B14: =(A14-1)*$C$6 -> 0.090331152 | C14: =$C$7*B14 -> 0.69444444 | D14: =0.5*c_rho*'P3 Energie'!E8*'P3 Energie'!E7*(C14-c_Vv)^2+'P3 Energie'!E13+'P3 Energie'!E15+'P3 Energie'!E6*$C$7 -> 18411.459 | E14: =D14*C14 -> 12785.735 | F14: 6 | G14: =(F14-1)*$H$6 -> 0.090266641 | H14: =$H$7*G14 -> 0.69444444 | I14: =0.5*c_rho*'P3 Energie'!F8*'P3 Energie'!F7*(H14-c_Vv)^2+'P3 Energie'!F13+'P3 Energie'!F15+'P3 Energie'!F6*$H$7 -> 19239.303 | J14: =I14*H14 -> 13360.627
A15: 7 | B15: =(A15-1)*$C$6 -> 0.10839738 | C15: =$C$7*B15 -> 0.83333333 | D15: =0.5*c_rho*'P3 Energie'!E8*'P3 Energie'!E7*(C15-c_Vv)^2+'P3 Energie'!E13+'P3 Energie'!E15+'P3 Energie'!E6*$C$7 -> 18411.544 | E15: =D15*C15 -> 15342.953 | F15: 7 | G15: =(F15-1)*$H$6 -> 0.10831997 | H15: =$H$7*G15 -> 0.83333333 | I15: =0.5*c_rho*'P3 Energie'!F8*'P3 Energie'!F7*(H15-c_Vv)^2+'P3 Energie'!F13+'P3 Energie'!F15+'P3 Energie'!F6*$H$7 -> 19239.376 | J15: =I15*H15 -> 16032.814
A16: 8 | B16: =(A16-1)*$C$6 -> 0.12646361 | C16: =$C$7*B16 -> 0.97222222 | D16: =0.5*c_rho*'P3 Energie'!E8*'P3 Energie'!E7*(C16-c_Vv)^2+'P3 Energie'!E13+'P3 Energie'!E15+'P3 Energie'!E6*$C$7 -> 18411.644 | E16: =D16*C16 -> 17900.209 | F16: 8 | G16: =(F16-1)*$H$6 -> 0.1263733 | H16: =$H$7*G16 -> 0.97222222 | I16: =0.5*c_rho*'P3 Energie'!F8*'P3 Energie'!F7*(H16-c_Vv)^2+'P3 Energie'!F13+'P3 Energie'!F15+'P3 Energie'!F6*$H$7 -> 19239.463 | J16: =I16*H16 -> 18705.034
A17: 9 | B17: =(A17-1)*$C$6 -> 0.14452984 | C17: =$C$7*B17 -> 1.1111111 | D17: =0.5*c_rho*'P3 Energie'!E8*'P3 Energie'!E7*(C17-c_Vv)^2+'P3 Energie'!E13+'P3 Energie'!E15+'P3 Energie'!E6*$C$7 -> 18411.759 | E17: =D17*C17 -> 20457.51 | F17: 9 | G17: =(F17-1)*$H$6 -> 0.14442663 | H17: =$H$7*G17 -> 1.1111111 | I17: =0.5*c_rho*'P3 Energie'!F8*'P3 Energie'!F7*(H17-c_Vv)^2+'P3 Energie'!F13+'P3 Energie'!F15+'P3 Energie'!F6*$H$7 -> 19239.564 | J17: =I17*H17 -> 21377.293
A18: 10 | B18: =(A18-1)*$C$6 -> 0.16259607 | C18: =$C$7*B18 -> 1.25 | D18: =0.5*c_rho*'P3 Energie'!E8*'P3 Energie'!E7*(C18-c_Vv)^2+'P3 Energie'!E13+'P3 Energie'!E15+'P3 Energie'!E6*$C$7 -> 18411.89 | E18: =D18*C18 -> 23014.863 | F18: 10 | G18: =(F18-1)*$H$6 -> 0.16247995 | H18: =$H$7*G18 -> 1.25 | I18: =0.5*c_rho*'P3 Energie'!F8*'P3 Energie'!F7*(H18-c_Vv)^2+'P3 Energie'!F13+'P3 Energie'!F15+'P3 Energie'!F6*$H$7 -> 19239.678 | J18: =I18*H18 -> 24049.597
A19: 11 | B19: =(A19-1)*$C$6 -> 0.1806623 | C19: =$C$7*B19 -> 1.3888889 | D19: =0.5*c_rho*'P3 Energie'!E8*'P3 Energie'!E7*(C19-c_Vv)^2+'P3 Energie'!E13+'P3 Energie'!E15+'P3 Energie'!E6*$C$7 -> 18412.037 | E19: =D19*C19 -> 25572.273 | F19: 11 | G19: =(F19-1)*$H$6 -> 0.18053328 | H19: =$H$7*G19 -> 1.3888889 | I19: =0.5*c_rho*'P3 Energie'!F8*'P3 Energie'!F7*(H19-c_Vv)^2+'P3 Energie'!F13+'P3 Energie'!F15+'P3 Energie'!F6*$H$7 -> 19239.805 | J19: =I19*H19 -> 26721.951
A20: 12 | B20: =(A20-1)*$C$6 -> 0.19872853 | C20: =$C$7*B20 -> 1.5277778 | D20: =0.5*c_rho*'P3 Energie'!E8*'P3 Energie'!E7*(C20-c_Vv)^2+'P3 Energie'!E13+'P3 Energie'!E15+'P3 Energie'!E6*$C$7 -> 18412.199 | E20: =D20*C20 -> 28129.748 | F20: 12 | G20: =(F20-1)*$H$6 -> 0.19858661 | H20: =$H$7*G20 -> 1.5277778 | I20: =0.5*c_rho*'P3 Energie'!F8*'P3 Energie'!F7*(H20-c_Vv)^2+'P3 Energie'!F13+'P3 Energie'!F15+'P3 Energie'!F6*$H$7 -> 19239.945 | J20: =I20*H20 -> 29394.361
A21: 13 | B21: =(A21-1)*$C$6 -> 0.21679476 | C21: =$C$7*B21 -> 1.6666667 | D21: =0.5*c_rho*'P3 Energie'!E8*'P3 Energie'!E7*(C21-c_Vv)^2+'P3 Energie'!E13+'P3 Energie'!E15+'P3 Energie'!E6*$C$7 -> 18412.376 | E21: =D21*C21 -> 30687.293 | F21: 13 | G21: =(F21-1)*$H$6 -> 0.21663994 | H21: =$H$7*G21 -> 1.6666667 | I21: =0.5*c_rho*'P3 Energie'!F8*'P3 Energie'!F7*(H21-c_Vv)^2+'P3 Energie'!F13+'P3 Energie'!F15+'P3 Energie'!F6*$H$7 -> 19240.099 | J21: =I21*H21 -> 32066.832
A22: 14 | B22: =(A22-1)*$C$6 -> 0.23486099 | C22: =$C$7*B22 -> 1.8055556 | D22: =0.5*c_rho*'P3 Energie'!E8*'P3 Energie'!E7*(C22-c_Vv)^2+'P3 Energie'!E13+'P3 Energie'!E15+'P3 Energie'!E6*$C$7 -> 18412.568 | E22: =D22*C22 -> 33244.915 | F22: 14 | G22: =(F22-1)*$H$6 -> 0.23469327 | H22: =$H$7*G22 -> 1.8055556 | I22: =0.5*c_rho*'P3 Energie'!F8*'P3 Energie'!F7*(H22-c_Vv)^2+'P3 Energie'!F13+'P3 Energie'!F15+'P3 Energie'!F6*$H$7 -> 19240.267 | J22: =I22*H22 -> 34739.37
A23: 15 | B23: =(A23-1)*$C$6 -> 0.25292722 | C23: =$C$7*B23 -> 1.9444444 | D23: =0.5*c_rho*'P3 Energie'!E8*'P3 Energie'!E7*(C23-c_Vv)^2+'P3 Energie'!E13+'P3 Energie'!E15+'P3 Energie'!E6*$C$7 -> 18412.776 | E23: =D23*C23 -> 35802.621 | F23: 15 | G23: =(F23-1)*$H$6 -> 0.2527466 | H23: =$H$7*G23 -> 1.9444444 | I23: =0.5*c_rho*'P3 Energie'!F8*'P3 Energie'!F7*(H23-c_Vv)^2+'P3 Energie'!F13+'P3 Energie'!F15+'P3 Energie'!F6*$H$7 -> 19240.447 | J23: =I23*H23 -> 37411.981
A24: 16 | B24: =(A24-1)*$C$6 -> 0.27099346 | C24: =$C$7*B24 -> 2.0833333 | D24: =0.5*c_rho*'P3 Energie'!E8*'P3 Energie'!E7*(C24-c_Vv)^2+'P3 Energie'!E13+'P3 Energie'!E15+'P3 Energie'!E6*$C$7 -> 18413 | E24: =D24*C24 -> 38360.416 | F24: 16 | G24: =(F24-1)*$H$6 -> 0.27079992 | H24: =$H$7*G24 -> 2.0833333 | I24: =0.5*c_rho*'P3 Energie'!F8*'P3 Energie'!F7*(H24-c_Vv)^2+'P3 Energie'!F13+'P3 Energie'!F15+'P3 Energie'!F6*$H$7 -> 19240.642 | J24: =I24*H24 -> 40084.67
A25: 17 | B25: =(A25-1)*$C$6 -> 0.28905969 | C25: =$C$7*B25 -> 2.2222222 | D25: =0.5*c_rho*'P3 Energie'!E8*'P3 Energie'!E7*(C25-c_Vv)^2+'P3 Energie'!E13+'P3 Energie'!E15+'P3 Energie'!E6*$C$7 -> 18413.239 | E25: =D25*C25 -> 40918.308 | F25: 17 | G25: =(F25-1)*$H$6 -> 0.28885325 | H25: =$H$7*G25 -> 2.2222222 | I25: =0.5*c_rho*'P3 Energie'!F8*'P3 Energie'!F7*(H25-c_Vv)^2+'P3 Energie'!F13+'P3 Energie'!F15+'P3 Energie'!F6*$H$7 -> 19240.849 | J25: =I25*H25 -> 42757.442
A26: 18 | B26: =(A26-1)*$C$6 -> 0.30712592 | C26: =$C$7*B26 -> 2.3611111 | D26: =0.5*c_rho*'P3 Energie'!E8*'P3 Energie'!E7*(C26-c_Vv)^2+'P3 Energie'!E13+'P3 Energie'!E15+'P3 Energie'!E6*$C$7 -> 18413.493 | E26: =D26*C26 -> 43476.303 | F26: 18 | G26: =(F26-1)*$H$6 -> 0.30690658 | H26: =$H$7*G26 -> 2.3611111 | I26: =0.5*c_rho*'P3 Energie'!F8*'P3 Energie'!F7*(H26-c_Vv)^2+'P3 Energie'!F13+'P3 Energie'!F15+'P3 Energie'!F6*$H$7 -> 19241.07 | J26: =I26*H26 -> 45430.304
A27: 19 | B27: =(A27-1)*$C$6 -> 0.32519215 | C27: =$C$7*B27 -> 2.5 | D27: =0.5*c_rho*'P3 Energie'!E8*'P3 Energie'!E7*(C27-c_Vv)^2+'P3 Energie'!E13+'P3 Energie'!E15+'P3 Energie'!E6*$C$7 -> 18413.763 | E27: =D27*C27 -> 46034.407 | F27: 19 | G27: =(F27-1)*$H$6 -> 0.32495991 | H27: =$H$7*G27 -> 2.5 | I27: =0.5*c_rho*'P3 Energie'!F8*'P3 Energie'!F7*(H27-c_Vv)^2+'P3 Energie'!F13+'P3 Energie'!F15+'P3 Energie'!F6*$H$7 -> 19241.304 | J27: =I27*H27 -> 48103.261
A28: 20 | B28: =(A28-1)*$C$6 -> 0.34325838 | C28: =$C$7*B28 -> 2.6388889 | D28: =0.5*c_rho*'P3 Energie'!E8*'P3 Energie'!E7*(C28-c_Vv)^2+'P3 Energie'!E13+'P3 Energie'!E15+'P3 Energie'!E6*$C$7 -> 18414.048 | E28: =D28*C28 -> 48592.626 | F28: 20 | G28: =(F28-1)*$H$6 -> 0.34301324 | H28: =$H$7*G28 -> 2.6388889 | I28: =0.5*c_rho*'P3 Energie'!F8*'P3 Energie'!F7*(H28-c_Vv)^2+'P3 Energie'!F13+'P3 Energie'!F15+'P3 Energie'!F6*$H$7 -> 19241.552 | J28: =I28*H28 -> 50776.318
A29: 21 | B29: =(A29-1)*$C$6 -> 0.36132461 | C29: =$C$7*B29 -> 2.7777778 | D29: =0.5*c_rho*'P3 Energie'!E8*'P3 Energie'!E7*(C29-c_Vv)^2+'P3 Energie'!E13+'P3 Energie'!E15+'P3 Energie'!E6*$C$7 -> 18414.348 | E29: =D29*C29 -> 51150.967 | F29: 21 | G29: =(F29-1)*$H$6 -> 0.36106657 | H29: =$H$7*G29 -> 2.7777778 | I29: =0.5*c_rho*'P3 Energie'!F8*'P3 Energie'!F7*(H29-c_Vv)^2+'P3 Energie'!F13+'P3 Energie'!F15+'P3 Energie'!F6*$H$7 -> 19241.813 | J29: =I29*H29 -> 53449.481
A30: 22 | B30: =(A30-1)*$C$6 -> 0.37939084 | C30: =$C$7*B30 -> 2.9166667 | D30: =0.5*c_rho*'P3 Energie'!E8*'P3 Energie'!E7*(C30-c_Vv)^2+'P3 Energie'!E13+'P3 Energie'!E15+'P3 Energie'!E6*$C$7 -> 18414.664 | E30: =D30*C30 -> 53709.437 | F30: 22 | G30: =(F30-1)*$H$6 -> 0.37911989 | H30: =$H$7*G30 -> 2.9166667 | I30: =0.5*c_rho*'P3 Energie'!F8*'P3 Energie'!F7*(H30-c_Vv)^2+'P3 Energie'!F13+'P3 Energie'!F15+'P3 Energie'!F6*$H$7 -> 19242.088 | J30: =I30*H30 -> 56122.755
A31: 23 | B31: =(A31-1)*$C$6 -> 0.39745707 | C31: =$C$7*B31 -> 3.0555556 | D31: =0.5*c_rho*'P3 Energie'!E8*'P3 Energie'!E7*(C31-c_Vv)^2+'P3 Energie'!E13+'P3 Energie'!E15+'P3 Energie'!E6*$C$7 -> 18414.996 | E31: =D31*C31 -> 56268.042 | F31: 23 | G31: =(F31-1)*$H$6 -> 0.39717322 | H31: =$H$7*G31 -> 3.0555556 | I31: =0.5*c_rho*'P3 Energie'!F8*'P3 Energie'!F7*(H31-c_Vv)^2+'P3 Energie'!F13+'P3 Energie'!F15+'P3 Energie'!F6*$H$7 -> 19242.375 | J31: =I31*H31 -> 58796.147
A32: 24 | B32: =(A32-1)*$C$6 -> 0.4155233 | C32: =$C$7*B32 -> 3.1944444 | D32: =0.5*c_rho*'P3 Energie'!E8*'P3 Energie'!E7*(C32-c_Vv)^2+'P3 Energie'!E13+'P3 Energie'!E15+'P3 Energie'!E6*$C$7 -> 18415.342 | E32: =D32*C32 -> 58826.788 | F32: 24 | G32: =(F32-1)*$H$6 -> 0.41522655 | H32: =$H$7*G32 -> 3.1944444 | I32: =0.5*c_rho*'P3 Energie'!F8*'P3 Energie'!F7*(H32-c_Vv)^2+'P3 Energie'!F13+'P3 Energie'!F15+'P3 Energie'!F6*$H$7 -> 19242.677 | J32: =I32*H32 -> 61469.662
A33: 25 | B33: =(A33-1)*$C$6 -> 0.43358953 | C33: =$C$7*B33 -> 3.3333333 | D33: =0.5*c_rho*'P3 Energie'!E8*'P3 Energie'!E7*(C33-c_Vv)^2+'P3 Energie'!E13+'P3 Energie'!E15+'P3 Energie'!E6*$C$7 -> 18415.704 | E33: =D33*C33 -> 61385.681 | F33: 25 | G33: =(F33-1)*$H$6 -> 0.43327988 | H33: =$H$7*G33 -> 3.3333333 | I33: =0.5*c_rho*'P3 Energie'!F8*'P3 Energie'!F7*(H33-c_Vv)^2+'P3 Energie'!F13+'P3 Energie'!F15+'P3 Energie'!F6*$H$7 -> 19242.991 | J33: =I33*H33 -> 64143.304
A34: 26 | B34: =(A34-1)*$C$6 -> 0.45165576 | C34: =$C$7*B34 -> 3.4722222 | D34: =0.5*c_rho*'P3 Energie'!E8*'P3 Energie'!E7*(C34-c_Vv)^2+'P3 Energie'!E13+'P3 Energie'!E15+'P3 Energie'!E6*$C$7 -> 18416.082 | E34: =D34*C34 -> 63944.729 | F34: 26 | G34: =(F34-1)*$H$6 -> 0.45133321 | H34: =$H$7*G34 -> 3.4722222 | I34: =0.5*c_rho*'P3 Energie'!F8*'P3 Energie'!F7*(H34-c_Vv)^2+'P3 Energie'!F13+'P3 Energie'!F15+'P3 Energie'!F6*$H$7 -> 19243.319 | J34: =I34*H34 -> 66817.081
A35: 27 | B35: =(A35-1)*$C$6 -> 0.46972199 | C35: =$C$7*B35 -> 3.6111111 | D35: =0.5*c_rho*'P3 Energie'!E8*'P3 Energie'!E7*(C35-c_Vv)^2+'P3 Energie'!E13+'P3 Energie'!E15+'P3 Energie'!E6*$C$7 -> 18416.475 | E35: =D35*C35 -> 66503.937 | F35: 27 | G35: =(F35-1)*$H$6 -> 0.46938653 | H35: =$H$7*G35 -> 3.6111111 | I35: =0.5*c_rho*'P3 Energie'!F8*'P3 Energie'!F7*(H35-c_Vv)^2+'P3 Energie'!F13+'P3 Energie'!F15+'P3 Energie'!F6*$H$7 -> 19243.661 | J35: =I35*H35 -> 69490.997
A36: 28 | B36: =(A36-1)*$C$6 -> 0.48778822 | C36: =$C$7*B36 -> 3.75 | D36: =0.5*c_rho*'P3 Energie'!E8*'P3 Energie'!E7*(C36-c_Vv)^2+'P3 Energie'!E13+'P3 Energie'!E15+'P3 Energie'!E6*$C$7 -> 18416.883 | E36: =D36*C36 -> 69063.312 | F36: 28 | G36: =(F36-1)*$H$6 -> 0.48743986 | H36: =$H$7*G36 -> 3.75 | I36: =0.5*c_rho*'P3 Energie'!F8*'P3 Energie'!F7*(H36-c_Vv)^2+'P3 Energie'!F13+'P3 Energie'!F15+'P3 Energie'!F6*$H$7 -> 19244.016 | J36: =I36*H36 -> 72165.058
A37: 29 | B37: =(A37-1)*$C$6 -> 0.50585445 | C37: =$C$7*B37 -> 3.8888889 | D37: =0.5*c_rho*'P3 Energie'!E8*'P3 Energie'!E7*(C37-c_Vv)^2+'P3 Energie'!E13+'P3 Energie'!E15+'P3 Energie'!E6*$C$7 -> 18417.307 | E37: =D37*C37 -> 71622.861 | F37: 29 | G37: =(F37-1)*$H$6 -> 0.50549319 | H37: =$H$7*G37 -> 3.8888889 | I37: =0.5*c_rho*'P3 Energie'!F8*'P3 Energie'!F7*(H37-c_Vv)^2+'P3 Energie'!F13+'P3 Energie'!F15+'P3 Energie'!F6*$H$7 -> 19244.384 | J37: =I37*H37 -> 74839.27
A38: 30 | B38: =(A38-1)*$C$6 -> 0.52392068 | C38: =$C$7*B38 -> 4.0277778 | D38: =0.5*c_rho*'P3 Energie'!E8*'P3 Energie'!E7*(C38-c_Vv)^2+'P3 Energie'!E13+'P3 Energie'!E15+'P3 Energie'!E6*$C$7 -> 18417.746 | E38: =D38*C38 -> 74182.589 | F38: 30 | G38: =(F38-1)*$H$6 -> 0.52354652 | H38: =$H$7*G38 -> 4.0277778 | I38: =0.5*c_rho*'P3 Energie'!F8*'P3 Energie'!F7*(H38-c_Vv)^2+'P3 Energie'!F13+'P3 Energie'!F15+'P3 Energie'!F6*$H$7 -> 19244.765 | J38: =I38*H38 -> 77513.638
A39: 31 | B39: =(A39-1)*$C$6 -> 0.54198691 | C39: =$C$7*B39 -> 4.1666667 | D39: =0.5*c_rho*'P3 Energie'!E8*'P3 Energie'!E7*(C39-c_Vv)^2+'P3 Energie'!E13+'P3 Energie'!E15+'P3 Energie'!E6*$C$7 -> 18418.201 | E39: =D39*C39 -> 76742.504 | F39: 31 | G39: =(F39-1)*$H$6 -> 0.54159985 | H39: =$H$7*G39 -> 4.1666667 | I39: =0.5*c_rho*'P3 Energie'!F8*'P3 Energie'!F7*(H39-c_Vv)^2+'P3 Energie'!F13+'P3 Energie'!F15+'P3 Energie'!F6*$H$7 -> 19245.16 | J39: =I39*H39 -> 80188.168
A40: 32 | B40: =(A40-1)*$C$6 -> 0.56005314 | C40: =$C$7*B40 -> 4.3055556 | D40: =0.5*c_rho*'P3 Energie'!E8*'P3 Energie'!E7*(C40-c_Vv)^2+'P3 Energie'!E13+'P3 Energie'!E15+'P3 Energie'!E6*$C$7 -> 18418.671 | E40: =D40*C40 -> 79302.611 | F40: 32 | G40: =(F40-1)*$H$6 -> 0.55965318 | H40: =$H$7*G40 -> 4.3055556 | I40: =0.5*c_rho*'P3 Energie'!F8*'P3 Energie'!F7*(H40-c_Vv)^2+'P3 Energie'!F13+'P3 Energie'!F15+'P3 Energie'!F6*$H$7 -> 19245.569 | J40: =I40*H40 -> 82862.865
...

Sheet P3 n=1000
A1: P3 – discretizarea intervalului [0, t1] în n = 1000 intervale egale
A2: Indicii ca în curs (și în Matlab): i = 1 … n+1, t_i = (i − 1)·Δt. P01-med = (1/n)·Σ(i=1..n) Fti·Vti folosește valorile de la începutul intervalelor; W01 = Σ(i=1..n+1) Pti·Δt, cu P(t_1) = 0, folosește valorile de la sfârșitul intervalelor. Cele două sume încadrează valoarea exactă.
A3: Vehicul mediu | F3: GT 63
B4: P01-med [W] | C4: =SUM(E9:E1008)/1000 -> 127995.17 | G4: P01-med [W] | H4: =SUM(J9:J1008)/1000 -> 133703.48
B5: W01 [Ws] | C5: =SUM(E9:E1009)*C6 -> 231702.93 | G5: W01 [Ws] | H5: =SUM(J9:J1009)*H6 -> 241863.37
B6: Δt [s] | C6: ='P3 Energie'!E24/1000 -> 0.001806623 | G6: Δt [s] | H6: ='P3 Energie'!F24/1000 -> 0.0018053328
B7: a [m/s²] | C7: ='P3 Energie'!E19 -> 7.6877625 | G7: a [m/s²] | H7: ='P3 Energie'!F19 -> 7.6932567
A8: i | B8: t_i [s] | C8: V_ti [m/s] | D8: F_ti [N] | E8: P_ti [W] | F8: i | G8: t_i [s] | H8: V_ti [m/s] | I8: F_ti [N] | J8: P_ti [W]
A9: 1 | B9: =(A9-1)*$C$6 -> 0 | C9: =$C$7*B9 -> 0 | D9: =0.5*c_rho*'P3 Energie'!E8*'P3 Energie'!E7*(C9-c_Vv)^2+'P3 Energie'!E13+'P3 Energie'!E15+'P3 Energie'!E6*$C$7 -> 18411.266 | E9: =D9*C9 -> 0 | F9: 1 | G9: =(F9-1)*$H$6 -> 0 | H9: =$H$7*G9 -> 0 | I9: =0.5*c_rho*'P3 Energie'!F8*'P3 Energie'!F7*(H9-c_Vv)^2+'P3 Energie'!F13+'P3 Energie'!F15+'P3 Energie'!F6*$H$7 -> 19239.135 | J9: =I9*H9 -> 0
A10: 2 | B10: =(A10-1)*$C$6 -> 0.001806623 | C10: =$C$7*B10 -> 0.013888889 | D10: =0.5*c_rho*'P3 Energie'!E8*'P3 Energie'!E7*(C10-c_Vv)^2+'P3 Energie'!E13+'P3 Energie'!E15+'P3 Energie'!E6*$C$7 -> 18411.266 | E10: =D10*C10 -> 255.71203 | F10: 2 | G10: =(F10-1)*$H$6 -> 0.0018053328 | H10: =$H$7*G10 -> 0.013888889 | I10: =0.5*c_rho*'P3 Energie'!F8*'P3 Energie'!F7*(H10-c_Vv)^2+'P3 Energie'!F13+'P3 Energie'!F15+'P3 Energie'!F6*$H$7 -> 19239.135 | J10: =I10*H10 -> 267.21021
A11: 3 | B11: =(A11-1)*$C$6 -> 0.0036132461 | C11: =$C$7*B11 -> 0.027777778 | D11: =0.5*c_rho*'P3 Energie'!E8*'P3 Energie'!E7*(C11-c_Vv)^2+'P3 Energie'!E13+'P3 Energie'!E15+'P3 Energie'!E6*$C$7 -> 18411.266 | E11: =D11*C11 -> 511.42407 | F11: 3 | G11: =(F11-1)*$H$6 -> 0.0036106657 | H11: =$H$7*G11 -> 0.027777778 | I11: =0.5*c_rho*'P3 Energie'!F8*'P3 Energie'!F7*(H11-c_Vv)^2+'P3 Energie'!F13+'P3 Energie'!F15+'P3 Energie'!F6*$H$7 -> 19239.136 | J11: =I11*H11 -> 534.42043
A12: 4 | B12: =(A12-1)*$C$6 -> 0.0054198691 | C12: =$C$7*B12 -> 0.041666667 | D12: =0.5*c_rho*'P3 Energie'!E8*'P3 Energie'!E7*(C12-c_Vv)^2+'P3 Energie'!E13+'P3 Energie'!E15+'P3 Energie'!E6*$C$7 -> 18411.267 | E12: =D12*C12 -> 767.13612 | F12: 4 | G12: =(F12-1)*$H$6 -> 0.0054159985 | H12: =$H$7*G12 -> 0.041666667 | I12: =0.5*c_rho*'P3 Energie'!F8*'P3 Energie'!F7*(H12-c_Vv)^2+'P3 Energie'!F13+'P3 Energie'!F15+'P3 Energie'!F6*$H$7 -> 19239.136 | J12: =I12*H12 -> 801.63066
A13: 5 | B13: =(A13-1)*$C$6 -> 0.0072264921 | C13: =$C$7*B13 -> 0.055555556 | D13: =0.5*c_rho*'P3 Energie'!E8*'P3 Energie'!E7*(C13-c_Vv)^2+'P3 Energie'!E13+'P3 Energie'!E15+'P3 Energie'!E6*$C$7 -> 18411.267 | E13: =D13*C13 -> 1022.8482 | F13: 5 | G13: =(F13-1)*$H$6 -> 0.0072213313 | H13: =$H$7*G13 -> 0.055555556 | I13: =0.5*c_rho*'P3 Energie'!F8*'P3 Energie'!F7*(H13-c_Vv)^2+'P3 Energie'!F13+'P3 Energie'!F15+'P3 Energie'!F6*$H$7 -> 19239.136 | J13: =I13*H13 -> 1068.8409
A14: 6 | B14: =(A14-1)*$C$6 -> 0.0090331152 | C14: =$C$7*B14 -> 0.069444444 | D14: =0.5*c_rho*'P3 Energie'!E8*'P3 Energie'!E7*(C14-c_Vv)^2+'P3 Energie'!E13+'P3 Energie'!E15+'P3 Energie'!E6*$C$7 -> 18411.268 | E14: =D14*C14 -> 1278.5603 | F14: 6 | G14: =(F14-1)*$H$6 -> 0.0090266641 | H14: =$H$7*G14 -> 0.069444444 | I14: =0.5*c_rho*'P3 Energie'!F8*'P3 Energie'!F7*(H14-c_Vv)^2+'P3 Energie'!F13+'P3 Energie'!F15+'P3 Energie'!F6*$H$7 -> 19239.137 | J14: =I14*H14 -> 1336.0512
A15: 7 | B15: =(A15-1)*$C$6 -> 0.010839738 | C15: =$C$7*B15 -> 0.083333333 | D15: =0.5*c_rho*'P3 Energie'!E8*'P3 Energie'!E7*(C15-c_Vv)^2+'P3 Energie'!E13+'P3 Energie'!E15+'P3 Energie'!E6*$C$7 -> 18411.269 | E15: =D15*C15 -> 1534.2724 | F15: 7 | G15: =(F15-1)*$H$6 -> 0.010831997 | H15: =$H$7*G15 -> 0.083333333 | I15: =0.5*c_rho*'P3 Energie'!F8*'P3 Energie'!F7*(H15-c_Vv)^2+'P3 Energie'!F13+'P3 Energie'!F15+'P3 Energie'!F6*$H$7 -> 19239.138 | J15: =I15*H15 -> 1603.2615
A16: 8 | B16: =(A16-1)*$C$6 -> 0.012646361 | C16: =$C$7*B16 -> 0.097222222 | D16: =0.5*c_rho*'P3 Energie'!E8*'P3 Energie'!E7*(C16-c_Vv)^2+'P3 Energie'!E13+'P3 Energie'!E15+'P3 Energie'!E6*$C$7 -> 18411.27 | E16: =D16*C16 -> 1789.9846 | F16: 8 | G16: =(F16-1)*$H$6 -> 0.01263733 | H16: =$H$7*G16 -> 0.097222222 | I16: =0.5*c_rho*'P3 Energie'!F8*'P3 Energie'!F7*(H16-c_Vv)^2+'P3 Energie'!F13+'P3 Energie'!F15+'P3 Energie'!F6*$H$7 -> 19239.139 | J16: =I16*H16 -> 1870.4718
A17: 9 | B17: =(A17-1)*$C$6 -> 0.014452984 | C17: =$C$7*B17 -> 0.11111111 | D17: =0.5*c_rho*'P3 Energie'!E8*'P3 Energie'!E7*(C17-c_Vv)^2+'P3 Energie'!E13+'P3 Energie'!E15+'P3 Energie'!E6*$C$7 -> 18411.271 | E17: =D17*C17 -> 2045.6968 | F17: 9 | G17: =(F17-1)*$H$6 -> 0.014442663 | H17: =$H$7*G17 -> 0.11111111 | I17: =0.5*c_rho*'P3 Energie'!F8*'P3 Energie'!F7*(H17-c_Vv)^2+'P3 Energie'!F13+'P3 Energie'!F15+'P3 Energie'!F6*$H$7 -> 19239.14 | J17: =I17*H17 -> 2137.6822
A18: 10 | B18: =(A18-1)*$C$6 -> 0.016259607 | C18: =$C$7*B18 -> 0.125 | D18: =0.5*c_rho*'P3 Energie'!E8*'P3 Energie'!E7*(C18-c_Vv)^2+'P3 Energie'!E13+'P3 Energie'!E15+'P3 Energie'!E6*$C$7 -> 18411.272 | E18: =D18*C18 -> 2301.4091 | F18: 10 | G18: =(F18-1)*$H$6 -> 0.016247995 | H18: =$H$7*G18 -> 0.125 | I18: =0.5*c_rho*'P3 Energie'!F8*'P3 Energie'!F7*(H18-c_Vv)^2+'P3 Energie'!F13+'P3 Energie'!F15+'P3 Energie'!F6*$H$7 -> 19239.141 | J18: =I18*H18 -> 2404.8926
A19: 11 | B19: =(A19-1)*$C$6 -> 0.01806623 | C19: =$C$7*B19 -> 0.13888889 | D19: =0.5*c_rho*'P3 Energie'!E8*'P3 Energie'!E7*(C19-c_Vv)^2+'P3 Energie'!E13+'P3 Energie'!E15+'P3 Energie'!E6*$C$7 -> 18411.274 | E19: =D19*C19 -> 2557.1214 | F19: 11 | G19: =(F19-1)*$H$6 -> 0.018053328 | H19: =$H$7*G19 -> 0.13888889 | I19: =0.5*c_rho*'P3 Energie'!F8*'P3 Energie'!F7*(H19-c_Vv)^2+'P3 Energie'!F13+'P3 Energie'!F15+'P3 Energie'!F6*$H$7 -> 19239.142 | J19: =I19*H19 -> 2672.1031
A20: 12 | B20: =(A20-1)*$C$6 -> 0.019872853 | C20: =$C$7*B20 -> 0.15277778 | D20: =0.5*c_rho*'P3 Energie'!E8*'P3 Energie'!E7*(C20-c_Vv)^2+'P3 Energie'!E13+'P3 Energie'!E15+'P3 Energie'!E6*$C$7 -> 18411.275 | E20: =D20*C20 -> 2812.8338 | F20: 12 | G20: =(F20-1)*$H$6 -> 0.019858661 | H20: =$H$7*G20 -> 0.15277778 | I20: =0.5*c_rho*'P3 Energie'!F8*'P3 Energie'!F7*(H20-c_Vv)^2+'P3 Energie'!F13+'P3 Energie'!F15+'P3 Energie'!F6*$H$7 -> 19239.143 | J20: =I20*H20 -> 2939.3136
A21: 13 | B21: =(A21-1)*$C$6 -> 0.021679476 | C21: =$C$7*B21 -> 0.16666667 | D21: =0.5*c_rho*'P3 Energie'!E8*'P3 Energie'!E7*(C21-c_Vv)^2+'P3 Energie'!E13+'P3 Energie'!E15+'P3 Energie'!E6*$C$7 -> 18411.277 | E21: =D21*C21 -> 3068.5462 | F21: 13 | G21: =(F21-1)*$H$6 -> 0.021663994 | H21: =$H$7*G21 -> 0.16666667 | I21: =0.5*c_rho*'P3 Energie'!F8*'P3 Energie'!F7*(H21-c_Vv)^2+'P3 Energie'!F13+'P3 Energie'!F15+'P3 Energie'!F6*$H$7 -> 19239.145 | J21: =I21*H21 -> 3206.5242
A22: 14 | B22: =(A22-1)*$C$6 -> 0.023486099 | C22: =$C$7*B22 -> 0.18055556 | D22: =0.5*c_rho*'P3 Energie'!E8*'P3 Energie'!E7*(C22-c_Vv)^2+'P3 Energie'!E13+'P3 Energie'!E15+'P3 Energie'!E6*$C$7 -> 18411.279 | E22: =D22*C22 -> 3324.2587 | F22: 14 | G22: =(F22-1)*$H$6 -> 0.023469327 | H22: =$H$7*G22 -> 0.18055556 | I22: =0.5*c_rho*'P3 Energie'!F8*'P3 Energie'!F7*(H22-c_Vv)^2+'P3 Energie'!F13+'P3 Energie'!F15+'P3 Energie'!F6*$H$7 -> 19239.147 | J22: =I22*H22 -> 3473.7348
A23: 15 | B23: =(A23-1)*$C$6 -> 0.025292722 | C23: =$C$7*B23 -> 0.19444444 | D23: =0.5*c_rho*'P3 Energie'!E8*'P3 Energie'!E7*(C23-c_Vv)^2+'P3 Energie'!E13+'P3 Energie'!E15+'P3 Energie'!E6*$C$7 -> 18411.281 | E23: =D23*C23 -> 3579.9714 | F23: 15 | G23: =(F23-1)*$H$6 -> 0.02527466 | H23: =$H$7*G23 -> 0.19444444 | I23: =0.5*c_rho*'P3 Energie'!F8*'P3 Energie'!F7*(H23-c_Vv)^2+'P3 Energie'!F13+'P3 Energie'!F15+'P3 Energie'!F6*$H$7 -> 19239.148 | J23: =I23*H23 -> 3740.9455
A24: 16 | B24: =(A24-1)*$C$6 -> 0.027099346 | C24: =$C$7*B24 -> 0.20833333 | D24: =0.5*c_rho*'P3 Energie'!E8*'P3 Energie'!E7*(C24-c_Vv)^2+'P3 Energie'!E13+'P3 Energie'!E15+'P3 Energie'!E6*$C$7 -> 18411.284 | E24: =D24*C24 -> 3835.6841 | F24: 16 | G24: =(F24-1)*$H$6 -> 0.027079992 | H24: =$H$7*G24 -> 0.20833333 | I24: =0.5*c_rho*'P3 Energie'!F8*'P3 Energie'!F7*(H24-c_Vv)^2+'P3 Energie'!F13+'P3 Energie'!F15+'P3 Energie'!F6*$H$7 -> 19239.15 | J24: =I24*H24 -> 4008.1563
A25: 17 | B25: =(A25-1)*$C$6 -> 0.028905969 | C25: =$C$7*B25 -> 0.22222222 | D25: =0.5*c_rho*'P3 Energie'!E8*'P3 Energie'!E7*(C25-c_Vv)^2+'P3 Energie'!E13+'P3 Energie'!E15+'P3 Energie'!E6*$C$7 -> 18411.286 | E25: =D25*C25 -> 4091.3969 | F25: 17 | G25: =(F25-1)*$H$6 -> 0.028885325 | H25: =$H$7*G25 -> 0.22222222 | I25: =0.5*c_rho*'P3 Energie'!F8*'P3 Energie'!F7*(H25-c_Vv)^2+'P3 Energie'!F13+'P3 Energie'!F15+'P3 Energie'!F6*$H$7 -> 19239.152 | J25: =I25*H25 -> 4275.3672
A26: 18 | B26: =(A26-1)*$C$6 -> 0.030712592 | C26: =$C$7*B26 -> 0.23611111 | D26: =0.5*c_rho*'P3 Energie'!E8*'P3 Energie'!E7*(C26-c_Vv)^2+'P3 Energie'!E13+'P3 Energie'!E15+'P3 Energie'!E6*$C$7 -> 18411.288 | E26: =D26*C26 -> 4347.1098 | F26: 18 | G26: =(F26-1)*$H$6 -> 0.030690658 | H26: =$H$7*G26 -> 0.23611111 | I26: =0.5*c_rho*'P3 Energie'!F8*'P3 Energie'!F7*(H26-c_Vv)^2+'P3 Energie'!F13+'P3 Energie'!F15+'P3 Energie'!F6*$H$7 -> 19239.155 | J26: =I26*H26 -> 4542.5782
A27: 19 | B27: =(A27-1)*$C$6 -> 0.032519215 | C27: =$C$7*B27 -> 0.25 | D27: =0.5*c_rho*'P3 Energie'!E8*'P3 Energie'!E7*(C27-c_Vv)^2+'P3 Energie'!E13+'P3 Energie'!E15+'P3 Energie'!E6*$C$7 -> 18411.291 | E27: =D27*C27 -> 4602.8228 | F27: 19 | G27: =(F27-1)*$H$6 -> 0.032495991 | H27: =$H$7*G27 -> 0.25 | I27: =0.5*c_rho*'P3 Energie'!F8*'P3 Energie'!F7*(H27-c_Vv)^2+'P3 Energie'!F13+'P3 Energie'!F15+'P3 Energie'!F6*$H$7 -> 19239.157 | J27: =I27*H27 -> 4809.7893
A28: 20 | B28: =(A28-1)*$C$6 -> 0.034325838 | C28: =$C$7*B28 -> 0.26388889 | D28: =0.5*c_rho*'P3 Energie'!E8*'P3 Energie'!E7*(C28-c_Vv)^2+'P3 Energie'!E13+'P3 Energie'!E15+'P3 Energie'!E6*$C$7 -> 18411.294 | E28: =D28*C28 -> 4858.5359 | F28: 20 | G28: =(F28-1)*$H$6 -> 0.034301324 | H28: =$H$7*G28 -> 0.26388889 | I28: =0.5*c_rho*'P3 Energie'!F8*'P3 Energie'!F7*(H28-c_Vv)^2+'P3 Energie'!F13+'P3 Energie'!F15+'P3 Energie'!F6*$H$7 -> 19239.159 | J28: =I28*H28 -> 5077.0004
A29: 21 | B29: =(A29-1)*$C$6 -> 0.036132461 | C29: =$C$7*B29 -> 0.27777778 | D29: =0.5*c_rho*'P3 Energie'!E8*'P3 Energie'!E7*(C29-c_Vv)^2+'P3 Energie'!E13+'P3 Energie'!E15+'P3 Energie'!E6*$C$7 -> 18411.297 | E29: =D29*C29 -> 5114.2492 | F29: 21 | G29: =(F29-1)*$H$6 -> 0.036106657 | H29: =$H$7*G29 -> 0.27777778 | I29: =0.5*c_rho*'P3 Energie'!F8*'P3 Energie'!F7*(H29-c_Vv)^2+'P3 Energie'!F13+'P3 Energie'!F15+'P3 Energie'!F6*$H$7 -> 19239.162 | J29: =I29*H29 -> 5344.2117
A30: 22 | B30: =(A30-1)*$C$6 -> 0.037939084 | C30: =$C$7*B30 -> 0.29166667 | D30: =0.5*c_rho*'P3 Energie'!E8*'P3 Energie'!E7*(C30-c_Vv)^2+'P3 Energie'!E13+'P3 Energie'!E15+'P3 Energie'!E6*$C$7 -> 18411.3 | E30: =D30*C30 -> 5369.9625 | F30: 22 | G30: =(F30-1)*$H$6 -> 0.037911989 | H30: =$H$7*G30 -> 0.29166667 | I30: =0.5*c_rho*'P3 Energie'!F8*'P3 Energie'!F7*(H30-c_Vv)^2+'P3 Energie'!F13+'P3 Energie'!F15+'P3 Energie'!F6*$H$7 -> 19239.165 | J30: =I30*H30 -> 5611.4231
A31: 23 | B31: =(A31-1)*$C$6 -> 0.039745707 | C31: =$C$7*B31 -> 0.30555556 | D31: =0.5*c_rho*'P3 Energie'!E8*'P3 Energie'!E7*(C31-c_Vv)^2+'P3 Energie'!E13+'P3 Energie'!E15+'P3 Energie'!E6*$C$7 -> 18411.303 | E31: =D31*C31 -> 5625.6761 | F31: 23 | G31: =(F31-1)*$H$6 -> 0.039717322 | H31: =$H$7*G31 -> 0.30555556 | I31: =0.5*c_rho*'P3 Energie'!F8*'P3 Energie'!F7*(H31-c_Vv)^2+'P3 Energie'!F13+'P3 Energie'!F15+'P3 Energie'!F6*$H$7 -> 19239.168 | J31: =I31*H31 -> 5878.6346
A32: 24 | B32: =(A32-1)*$C$6 -> 0.04155233 | C32: =$C$7*B32 -> 0.31944444 | D32: =0.5*c_rho*'P3 Energie'!E8*'P3 Energie'!E7*(C32-c_Vv)^2+'P3 Energie'!E13+'P3 Energie'!E15+'P3 Energie'!E6*$C$7 -> 18411.307 | E32: =D32*C32 -> 5881.3897 | F32: 24 | G32: =(F32-1)*$H$6 -> 0.041522655 | H32: =$H$7*G32 -> 0.31944444 | I32: =0.5*c_rho*'P3 Energie'!F8*'P3 Energie'!F7*(H32-c_Vv)^2+'P3 Energie'!F13+'P3 Energie'!F15+'P3 Energie'!F6*$H$7 -> 19239.171 | J32: =I32*H32 -> 6145.8462
A33: 25 | B33: =(A33-1)*$C$6 -> 0.043358953 | C33: =$C$7*B33 -> 0.33333333 | D33: =0.5*c_rho*'P3 Energie'!E8*'P3 Energie'!E7*(C33-c_Vv)^2+'P3 Energie'!E13+'P3 Energie'!E15+'P3 Energie'!E6*$C$7 -> 18411.311 | E33: =D33*C33 -> 6137.1035 | F33: 25 | G33: =(F33-1)*$H$6 -> 0.043327988 | H33: =$H$7*G33 -> 0.33333333 | I33: =0.5*c_rho*'P3 Energie'!F8*'P3 Energie'!F7*(H33-c_Vv)^2+'P3 Energie'!F13+'P3 Energie'!F15+'P3 Energie'!F6*$H$7 -> 19239.174 | J33: =I33*H33 -> 6413.058
A34: 26 | B34: =(A34-1)*$C$6 -> 0.045165576 | C34: =$C$7*B34 -> 0.34722222 | D34: =0.5*c_rho*'P3 Energie'!E8*'P3 Energie'!E7*(C34-c_Vv)^2+'P3 Energie'!E13+'P3 Energie'!E15+'P3 Energie'!E6*$C$7 -> 18411.314 | E34: =D34*C34 -> 6392.8175 | F34: 26 | G34: =(F34-1)*$H$6 -> 0.045133321 | H34: =$H$7*G34 -> 0.34722222 | I34: =0.5*c_rho*'P3 Energie'!F8*'P3 Energie'!F7*(H34-c_Vv)^2+'P3 Energie'!F13+'P3 Energie'!F15+'P3 Energie'!F6*$H$7 -> 19239.177 | J34: =I34*H34 -> 6680.2698
A35: 27 | B35: =(A35-1)*$C$6 -> 0.046972199 | C35: =$C$7*B35 -> 0.36111111 | D35: =0.5*c_rho*'P3 Energie'!E8*'P3 Energie'!E7*(C35-c_Vv)^2+'P3 Energie'!E13+'P3 Energie'!E15+'P3 Energie'!E6*$C$7 -> 18411.318 | E35: =D35*C35 -> 6648.5316 | F35: 27 | G35: =(F35-1)*$H$6 -> 0.046938653 | H35: =$H$7*G35 -> 0.36111111 | I35: =0.5*c_rho*'P3 Energie'!F8*'P3 Energie'!F7*(H35-c_Vv)^2+'P3 Energie'!F13+'P3 Energie'!F15+'P3 Energie'!F6*$H$7 -> 19239.181 | J35: =I35*H35 -> 6947.4819
A36: 28 | B36: =(A36-1)*$C$6 -> 0.048778822 | C36: =$C$7*B36 -> 0.375 | D36: =0.5*c_rho*'P3 Energie'!E8*'P3 Energie'!E7*(C36-c_Vv)^2+'P3 Energie'!E13+'P3 Energie'!E15+'P3 Energie'!E6*$C$7 -> 18411.322 | E36: =D36*C36 -> 6904.2459 | F36: 28 | G36: =(F36-1)*$H$6 -> 0.048743986 | H36: =$H$7*G36 -> 0.375 | I36: =0.5*c_rho*'P3 Energie'!F8*'P3 Energie'!F7*(H36-c_Vv)^2+'P3 Energie'!F13+'P3 Energie'!F15+'P3 Energie'!F6*$H$7 -> 19239.184 | J36: =I36*H36 -> 7214.694
A37: 29 | B37: =(A37-1)*$C$6 -> 0.050585445 | C37: =$C$7*B37 -> 0.38888889 | D37: =0.5*c_rho*'P3 Energie'!E8*'P3 Energie'!E7*(C37-c_Vv)^2+'P3 Energie'!E13+'P3 Energie'!E15+'P3 Energie'!E6*$C$7 -> 18411.327 | E37: =D37*C37 -> 7159.9603 | F37: 29 | G37: =(F37-1)*$H$6 -> 0.050549319 | H37: =$H$7*G37 -> 0.38888889 | I37: =0.5*c_rho*'P3 Energie'!F8*'P3 Energie'!F7*(H37-c_Vv)^2+'P3 Energie'!F13+'P3 Energie'!F15+'P3 Energie'!F6*$H$7 -> 19239.188 | J37: =I37*H37 -> 7481.9064
A38: 30 | B38: =(A38-1)*$C$6 -> 0.052392068 | C38: =$C$7*B38 -> 0.40277778 | D38: =0.5*c_rho*'P3 Energie'!E8*'P3 Energie'!E7*(C38-c_Vv)^2+'P3 Energie'!E13+'P3 Energie'!E15+'P3 Energie'!E6*$C$7 -> 18411.331 | E38: =D38*C38 -> 7415.675 | F38: 30 | G38: =(F38-1)*$H$6 -> 0.052354652 | H38: =$H$7*G38 -> 0.40277778 | I38: =0.5*c_rho*'P3 Energie'!F8*'P3 Energie'!F7*(H38-c_Vv)^2+'P3 Energie'!F13+'P3 Energie'!F15+'P3 Energie'!F6*$H$7 -> 19239.192 | J38: =I38*H38 -> 7749.1188
A39: 31 | B39: =(A39-1)*$C$6 -> 0.054198691 | C39: =$C$7*B39 -> 0.41666667 | D39: =0.5*c_rho*'P3 Energie'!E8*'P3 Energie'!E7*(C39-c_Vv)^2+'P3 Energie'!E13+'P3 Energie'!E15+'P3 Energie'!E6*$C$7 -> 18411.336 | E39: =D39*C39 -> 7671.3898 | F39: 31 | G39: =(F39-1)*$H$6 -> 0.054159985 | H39: =$H$7*G39 -> 0.41666667 | I39: =0.5*c_rho*'P3 Energie'!F8*'P3 Energie'!F7*(H39-c_Vv)^2+'P3 Energie'!F13+'P3 Energie'!F15+'P3 Energie'!F6*$H$7 -> 19239.196 | J39: =I39*H39 -> 8016.3315
A40: 32 | B40: =(A40-1)*$C$6 -> 0.056005314 | C40: =$C$7*B40 -> 0.43055556 | D40: =0.5*c_rho*'P3 Energie'!E8*'P3 Energie'!E7*(C40-c_Vv)^2+'P3 Energie'!E13+'P3 Energie'!E15+'P3 Energie'!E6*$C$7 -> 18411.34 | E40: =D40*C40 -> 7927.1048 | F40: 32 | G40: =(F40-1)*$H$6 -> 0.055965318 | H40: =$H$7*G40 -> 0.43055556 | I40: =0.5*c_rho*'P3 Energie'!F8*'P3 Energie'!F7*(H40-c_Vv)^2+'P3 Energie'!F13+'P3 Energie'!F15+'P3 Energie'!F6*$H$7 -> 19239.2 | J40: =I40*H40 -> 8283.5443
...

Sheet Baterie
A1: P3 – Calculul bateriei electrice (celule Li-ion)
A2: W_celulă = Cap·U; N = Wbat / W_celulă. Serie → tensiunea bateriei; paralel → curentul și capacitatea. Limitare: masa bateriei ≤ 30 % din masa vehiculului.
A4: Pas | B4: Mărime | C4: Simbol | D4: Unitate | E4: Vehicul mediu | F4: GT 63 (referință) | G4: Formulă / observație
A5: Date de intrare
B6: Energia necesară în baterie (P3, pasul 14) | C6: Wbat | D6: Ws | E6: ='P3 Energie'!E53 -> 3.757657e+08 | F6: ='P3 Energie'!F53 -> 4.3926672e+08
B7: Puterea maximă la axul mașinii (P2, pasul 5) | C7: P_max | D7: W | E7: ='P2 Putere'!E31 -> 518751.92 | F7: ='P2 Putere'!F31 -> 541696.97
B8: Masa vehiculului | C8: M | D8: kg | E8: ='Date documentare'!G16 -> 2355.8 | F8: ='Date documentare'!G6 -> 2460
A9: Numărul de celule
B10: Energia unei celule | C10: W_celulă | D10: Ws | E10: =cel_Cap*3600*cel_U_nom -> 64800 | F10: =cel_Cap*3600*cel_U_nom -> 64800 | G10: Cap [Ah→As] × U [V]
B11: Numărul minim de celule (energie) | C11: N_min | D11: - | E11: =ROUNDUP(E6/E10,0) -> 5799 | F11: =ROUNDUP(F6/F10,0) -> 6779
B12: Celule în serie | C12: Ns | D12: - | E12: =ROUNDDOWN(c_U_max/cel_U_max,0) -> 202 | F12: =ROUNDDOWN(c_U_max/cel_U_max,0) -> 202 | G12: Ns·U_max celulă ≤ tensiunea maximă admisă
B13: Tensiunea nominală a bateriei | C13: U_bat | D13: V | E13: =E12*cel_U_nom -> 727.2 | F13: =F12*cel_U_nom -> 727.2
B14: Tensiunea maximă (complet încărcată) | D14: V | E14: =E12*cel_U_max -> 848.4 | F14: =F12*cel_U_max -> 848.4
B15: Tensiunea minimă (descărcată) | D15: V | E15: =E12*cel_U_min -> 505 | F15: =F12*cel_U_min -> 505
B16: Ramuri în paralel – din energie | C16: Np | D16: - | E16: =ROUNDUP(E11/E12,0) -> 29 | F16: =ROUNDUP(F11/F12,0) -> 34
B17: Puterea electrică maximă cerută bateriei | D17: W | E17: =E7/c_eta -> 648439.9 | F17: =F7/c_eta -> 677121.21 | G17: P_max / η
B18: Curentul bateriei la P_max și tensiunea nominală | C18: I_bat | D18: A | E18: =E17/E13 -> 891.69403 | F18: =F17/F13 -> 931.13478
B19: Curentul maxim al bateriei (la tensiunea minimă) | C19: I_bat,max | D19: A | E19: =E17/E15 -> 1284.0394 | F19: =F17/F15 -> 1340.8341 | G19: caz defavorabil: baterie aproape descărcată
B20: Ramuri în paralel – din curent | C20: Np | D20: - | E20: =ROUNDUP(E19/cel_I,0) -> 22 | F20: =ROUNDUP(F19/cel_I,0) -> 23
B21: Ramuri în paralel (alese) | C21: Np | D21: - | E21: =MAX(E16,E20) -> 29 | F21: =MAX(F16,F20) -> 34
B22: Numărul total de celule | C22: N | D22: - | E22: =E12*E21 -> 5858 | F22: =F12*F21 -> 6868
