Workbook

Sheet Rezultate
A1: Etapa 1 de calcul – rezultate: dinamica longitudinală a Mercedes-AMG GT 63 4-Door Coupé
A2: Calcul după „Noțiuni generale de dinamica vehiculului” (curs CCA C1, L. Popescu, UPB). Toate valorile sunt formule legate de foile „Date de intrare” și „Calcul regimuri”.
A4: 1. Date principale
A5: Masa de calcul M | D5: =M_calc -> 2535 | E5: kg
A6: Cx · S | D6: =C_x*A_f -> 0.5368 | E6: m²
A7: Coeficient de rulare f / aderență μ | D7: =FIXED(f_r,3)&" / "&FIXED(mu_us,2) -> 0.012 / 0.85 | E7: –
A8: Raza dinamică a roții r_w | D8: =r_w -> 0.344544 | E8: m
A9: Raport de transmitere estimat i_g | D9: =i_g -> 5.6285679 | E9: –
A10: Randament transmisie η | D10: =eta_t -> 0.95 | E10: –
A11: Cuplu maxim / putere de vârf / putere continuă | D11: =FIXED(T_max,0,TRUE())&" N·m / "&FIXED(P_vf,0,TRUE())&" kW / "&FIXED(P_cont,0,TRUE())&" kW" -> 2000 N·m / 860 kW / 530 kW
A13: 2. Regimuri caracteristice (rel. 25–33, 35–43)
A14: Regim | B14: Descriere | C14: v [km/h] | D14: Pantă [%] | E14: a [m/s²] | F14: F_t nec. [N] | G14: T_w [N·m] | H14: P_w [kW] | I14: P_m [kW] | J14: T_m [N·m] | K14: n_m [rot/min] | L14: μ necesar | M14: Verificare (43) | N14: Limitare
A15: S1 | B15: Viteză maximă, drum orizontal | C15: ='Calcul regimuri'!E6 -> 300 | D15: ='Calcul regimuri'!E8 -> 0 | E15: ='Calcul regimuri'!E10 -> 0 | F15: ='Calcul regimuri'!E15 -> 2581.6841 | G15: ='Calcul regimuri'!E16 -> 889.50376 | H15: ='Calcul regimuri'!E17 -> 215.14034 | I15: ='Calcul regimuri'!E18 -> 226.46352 | J15: ='Calcul regimuri'!E19 -> 166.35133 | K15: ='Calcul regimuri'!E21 -> 13000 | L15: ='Calcul regimuri'!E24 -> 0.10381405 | M15: ='Calcul regimuri'!E29 -> ÎNDEPLINITĂ | N15: ='Calcul regimuri'!E28 -> acționare
A16: S2a | B16: Accelerare 0–100 km/h – la pornire (v = 0) | C16: ='Calcul regimuri'!F6 -> 0 | D16: ='Calcul regimuri'!F8 -> 0 | E16: ='Calcul regimuri'!F10 -> 11.574074 | F16: ='Calcul regimuri'!F15 -> 29638.698 | G16: ='Calcul regimuri'!F16 -> 10211.836 | H16: ='Calcul regimuri'!F17 -> 0 | I16: ='Calcul regimuri'!F18 -> 0 | J16: ='Calcul regimuri'!F19 -> 1909.7754 | K16: ='Calcul regimuri'!F21 -> 0 | L16: ='Calcul regimuri'!F24 -> 1.1918241 | M16: ='Calcul regimuri'!F29 -> NEÎNDEPLINITĂ | N16: ='Calcul regimuri'!F28 -> aderență
A17: S2b | B17: Accelerare 0–100 km/h – la 100 km/h | C17: ='Calcul regimuri'!G6 -> 100 | D17: ='Calcul regimuri'!G8 -> 0 | E17: ='Calcul regimuri'!G10 -> 11.574074 | F17: ='Calcul regimuri'!G15 -> 29892.394 | G17: ='Calcul regimuri'!G16 -> 10299.245 | H17: ='Calcul regimuri'!G17 -> 830.34428 | I17: ='Calcul regimuri'!G18 -> 874.04661 | J17: ='Calcul regimuri'!G19 -> 1926.1224 | K17: ='Calcul regimuri'!G21 -> 4333.3333 | L17: ='Calcul regimuri'!G24 -> 1.2020256 | M17: ='Calcul regimuri'!G29 -> NEÎNDEPLINITĂ | N17: ='Calcul regimuri'!G28 -> aderență
A18: S3 | B18: Rampă 10 % la 100 km/h, viteză constantă | C18: ='Calcul regimuri'!H6 -> 100 | D18: ='Calcul regimuri'!H8 -> 10 | E18: ='Calcul regimuri'!H10 -> 0 | F18: ='Calcul regimuri'!H15 -> 3025.1285 | G18: ='Calcul regimuri'!H16 -> 1042.2899 | H18: ='Calcul regimuri'!H17 -> 84.031347 | I18: ='Calcul regimuri'!H18 -> 88.45405 | J18: ='Calcul regimuri'!H19 -> 194.92476 | K18: ='Calcul regimuri'!H21 -> 4333.3333 | L18: ='Calcul regimuri'!H24 -> 0.12225244 | M18: ='Calcul regimuri'!H29 -> ÎNDEPLINITĂ | N18: ='Calcul regimuri'!H28 -> aderență
A19: S4 | B19: Pornire pe panta maximă 30 % (v ≈ 0, a = 0) | C19: ='Calcul regimuri'!I6 -> 0 | D19: ='Calcul regimuri'!I8 -> 30 | E19: ='Calcul regimuri'!I10 -> 0 | F19: ='Calcul regimuri'!I15 -> 7431.7025 | G19: ='Calcul regimuri'!I16 -> 2560.5485 | H19: ='Calcul regimuri'!I17 -> 0 | I19: ='Calcul regimuri'!I18 -> 0 | J19: ='Calcul regimuri'!I19 -> 478.86323 | K19: ='Calcul regimuri'!I21 -> 0 | L19: ='Calcul regimuri'!I24 -> 0.312 | M19: ='Calcul regimuri'!I29 -> ÎNDEPLINITĂ | N19: ='Calcul regimuri'!I28 -> aderență
A21: 3. Indicatori de performanță (model vs. date oficiale)
A22: Indicator | D22: Calculat | E22: Oficial | F22: Observație
A23: Timp 0–100 km/h, μ = 0,85 (asfalt uscat, tabel curs) | D23: =INDEX('Caracteristica tractiune'!O5:O65,MATCH(v_acc,'Caracteristica tractiune'!A5:A65,0)) -> 3.3928008 | E23: =t_acc -> 2.4 | F23: aderența limitează accelerarea
A24: Timp 0–100 km/h, μ = 1,20 (anvelope de performanță) | D24: =INDEX('Caracteristica tractiune'!P5:P65,MATCH(v_acc,'Caracteristica tractiune'!A5:A65,0)) -> 2.3912375 | E24: =t_acc -> 2.4 | F24: verifică performanța oficială
A25: Timp 0–200 km/h, μ = 1,20 | D25: =INDEX('Caracteristica tractiune'!P5:P65,MATCH(200,'Caracteristica tractiune'!A5:A65,0)) -> 6.1777767 | E25: =t_200 -> 6.8 | F25: peste ≈100 km/h limitează puterea de vârf
A26: Accelerația maximă la pornire, μ = 0,85 [m/s²] | D26: ='Calcul regimuri'!E37 -> 8.22078 | E26: =a_med -> 11.574074 | F26: oficial = accelerația medie 0–100
A27: Coeficient de aderență necesar pentru 0–100 în 2,4 s | D27: ='Calcul regimuri'!F24 -> 1.1918241 | E27: – | F27: regimul S2a
A28: Viteza maximă teoretică cu puterea continuă [km/h] | D28: ='Calcul regimuri'!E41 -> 405.50276 | E28: =v_max -> 300 | F28: v_max reală este limitată electronic / de turație
A29: Panta maximă (limită de aderență, μ = 0,85) [%] | D29: ='Calcul regimuri'!E38 -> 83.8 | E29: – | F29: tracțiune integrală
A30: Puterea motoarelor la v_max = 300 km/h [kW] | D30: ='Calcul regimuri'!E18 -> 226.46352 | E30: =P_cont -> 530 | F30: comparată cu puterea continuă
A32: 4. Concluzii
A33: ="1. La v_max = "&FIXED(v_max,0,TRUE())&" km/h pe drum orizontal sunt necesari F_t = "&FIXED('Calcul regimuri'!E15,0)&" N la roți, adică P_m = "&FIXED('Calcul regimuri'!E18,0,TRUE())&" kW – doar "&FIXED(100*('Calcul regimuri'!E31),0,TRUE())&" %"&" din puterea continuă; "&FIXED(100*('Calcul regimuri'!E11/'Calcul regimuri'!E15),0,TRUE())&" %"&" din rezistență este aerodinamică. Viteza maximă nu este limitată de putere, ci electronic și de turația motoarelor ("&FIXED('Calcul regimuri'!E21,0)&" rot/min)." -> 1. La v_max = 300 km/h pe drum orizontal sunt necesari F_t = 2,582 N la roți, adică P_m = 226 kW – doar 43 % din puterea continuă; 88 % din rezistență este aerodinamică. Viteza maximă nu este limitată de putere, ci electronic și de turația motoarelor (13,000 rot/min).
A34: ="2. Accelerarea 0–100 km/h în "&FIXED(t_acc,1)&" s cere o forță de "&FIXED('Calcul regimuri'!F15,0)&" N la pornire, deci μ ≥ "&FIXED('Calcul regimuri'!F24,2)&". Cu μ = "&FIXED(mu_us,2)&" (asfalt uscat, tabelul cursului) forța transmisibilă este doar "&FIXED('Calcul regimuri'!F23,0)&" N, iar timpul minim estimat este "&FIXED(D23,1)&" s: performanța este limitată de aderență, nu de acționare (F_t,drive = "&FIXED('Calcul regimuri'!F26,0)&" N)." -> 2. Accelerarea 0–100 km/h în 2.4 s cere o forță de 29,639 N la pornire, deci μ ≥ 1.19. Cu μ = 0.85 (asfalt uscat, tabelul cursului) forța transmisibilă este doar 21,138 N, iar timpul minim estimat este 3.4 s: performanța este limitată de aderență, nu de acționare (F_t,drive = 31,039 N).
A35: ="3. Cu anvelope de performanță (μ = "&FIXED(mu_perf,2)&") modelul dă 0–100 km/h în "&FIXED(D24,2)&" s (oficial "&FIXED(t_acc,1)&" s) și 0–200 km/h în "&FIXED(D25,1)&" s (oficial "&FIXED(t_200,1)&" s, abatere "&FIXED(100*(ABS(D25/t_200-1)),0,TRUE())&" %"&"). Abaterea la 0–200 km/h provine în principal din neglijarea maselor în rotație (δ = 1, rel. 23) și a pierderilor din invertor și baterie; ipotezele pentru r_w, i_g și η sunt plauzibile." -> 3. Cu anvelope de performanță (μ = 1.20) modelul dă 0–100 km/h în 2.39 s (oficial 2.4 s) și 0–200 km/h în 6.2 s (oficial 6.8 s, abatere 9 %). Abaterea la 0–200 km/h provine în principal din neglijarea maselor în rotație (δ = 1, rel. 23) și a pierderilor din invertor și baterie; ipotezele pentru r_w, i_g și η sunt plauzibile.
A36: ="4. La 100 km/h, accelerația medie impusă ar cere P_m = "&FIXED('Calcul regimuri'!G18,0,TRUE())&" kW ("&FIXED(100*('Calcul regimuri'!G32),0,TRUE())&" %"&" din puterea de vârf de "&FIXED(P_vf,0,TRUE())&" kW): accelerarea reală scade odată cu viteza, iar puterea de vârf este necesară doar pentru performanța maximă (Launch Control)." -> 4. La 100 km/h, accelerația medie impusă ar cere P_m = 874 kW (102 % din puterea de vârf de 860 kW): accelerarea reală scade odată cu viteza, iar puterea de vârf este necesară doar pentru performanța maximă (Launch Control).
A37: ="5. Rampa de "&FIXED(p_1,0,TRUE())&" % la "&FIXED(v_p1,0,TRUE())&" km/h cere "&FIXED('Calcul regimuri'!H18,0,TRUE())&" kW, iar pornirea pe panta de "&FIXED(p_max,0,TRUE())&" % cere "&FIXED('Calcul regimuri'!I15,0)&" N (μ_nec = "&FIXED('Calcul regimuri'!I24,2)&"): ambele sunt îndeplinite cu rezervă mare." -> 5. Rampa de 10 % la 100 km/h cere 88 kW, iar pornirea pe panta de 30 % cere 7,432 N (μ_nec = 0.31): ambele sunt îndeplinite cu rezervă mare.
A38: ="6. Date de confirmat în etapele următoare: dimensiunea anvelopelor (r_w), rapoartele reale de transmitere față/spate, distribuția cuplului între punți și cuplul continuu al motoarelor." -> 6. Date de confirmat în etapele următoare: dimensiunea anvelopelor (r_w), rapoartele reale de transmitere față/spate, distribuția cuplului între punți și cuplul continuu al motoarelor.

Sheet Date de intrare
A1: Etapa 1 de calcul – dinamica longitudinală: date de intrare
A2: Vehicul: Mercedes-AMG GT 63 4MATIC+ 4-Door Coupé (versiunea de serie a Concept AMG GT XX). Text albastru = valoare introdusă (modificabilă); text negru = formulă. Numele din coloana A pot fi folosite direct în formule (ex. =0,5*rho_aer*C_x*A_f*v^2).
A4: Nume | B4: Mărime | C4: Valoare | D4: Unitate | E4: Tip | F4: Sursă / justificare
A5: Vehicul
A6: M_DIN | B6: Masa proprie DIN (fără șofer) | C6: 2460 | D6: kg | E6: oficial | F6: Mercedes-Benz Media, comunicat de lansare 20.05.2026 (tabel tehnic)
A7: m_sofer | B7: Masa șoferului (convenția UE) | C7: 75 | D7: kg | E7: ipoteză | F7: Regulamentul UE 1230/2012: masa în ordine de mers include șoferul de 75 kg
A8: M_calc | B8: Masa totală de calcul M | C8: =M_DIN+m_sofer -> 2535 | D8: kg | E8: calculat | F8: Egală cu masa UE în ordine de mers: 2535 kg (valoare oficială)
A9: C_x | B9: Coeficient de rezistență aerodinamică Cx | C9: 0.22 | D9: – | E9: oficial | F9: Mercedes-Benz Media, comunicat de lansare 20.05.2026 (tabel tehnic)
A10: A_f | B10: Aria frontală S | C10: 2.44 | D10: m² | E10: oficial | F10: Mercedes-Benz Media, comunicat de lansare 20.05.2026 (tabel tehnic) (valoare publicată pentru gama AMG GT 4-Door Coupé electric)
A11: T_max | B11: Cuplul maxim al sistemului de propulsie T_m,max | C11: 2000 | D11: N·m | E11: oficial | F11: Mercedes-Benz Media, comunicat de lansare 20.05.2026 (tabel tehnic); considerat la arborii motoarelor (vezi ipoteza transmisiei)
A12: P_vf | B12: Puterea de vârf (AMG Launch Control) | C12: 860 | D12: kW | E12: oficial | F12: Mercedes-Benz Media, comunicat de lansare 20.05.2026 (tabel tehnic); disponibilă cel mult 63 s, la SoC ≥ 80 %
A13: P_cont | B13: Puterea continuă | C13: 530 | D13: kW | E13: oficial | F13: Mercedes-Benz Media, comunicat de lansare 20.05.2026 (tabel tehnic)
A14: v_max | B14: Viteza maximă (limitată electronic) | C14: 300 | D14: km/h | E14: oficial | F14: Mercedes-Benz Media, comunicat de lansare 20.05.2026 (tabel tehnic) (cu AMG Driver's Package)
A15: t_acc | B15: Timp de accelerare 0–100 km/h | C15: 2.4 | D15: s | E15: oficial | F15: Mercedes-Benz Media, comunicat de lansare 20.05.2026 (tabel tehnic) (2,1 s este cu „1-foot rollout”)
A16: t_200 | B16: Timp de accelerare 0–200 km/h | C16: 6.8 | D16: s | E16: oficial | F16: Mercedes-Benz Media, comunicat de lansare 20.05.2026 (tabel tehnic)
A17: Roată și transmisie
A18: D_jant | B18: Diametrul jantei | C18: 21 | D18: inch | E18: ipoteză | F18: Jante de 19″–21″ (oficial); se alege 21″, varianta cea mai performantă
A19: B_anv | B19: Lățimea anvelopei (punte spate) | C19: 295 | D19: mm | E19: ipoteză | F19: Dimensiunile anvelopelor versiunii electrice nu sunt publicate; se preia 295/30 R21 de la AMG GT 63 4-Door Coupé (V8). De confirmat în CoC.
A20: h_rap | B20: Raportul de aspect al anvelopei (înălțime/lățime) | C20: 0.3 | D20: – | E20: ipoteză | F20: Idem (profil 30)
A21: k_def | B21: Coeficient de deformare radială sub sarcină | C21: 0.97 | D21: – | E21: ipoteză | F21: Raza dinamică ≈ 0,96–0,98 × raza liberă (valoare uzuală)
A22: r_w | B22: Raza dinamică a roții r_w | C22: =k_def*(D_jant*25.4/2+B_anv*h_rap)/1000 -> 0.344544 | D22: m | E22: calculat | F22: Raza liberă = D_jantă/2 + B·h/B; r_w = k_def × raza liberă
A23: n_m_vmax | B23: Turația motoarelor de pe puntea spate la v_max | C23: 13000 | D23: rot/min | E23: oficial | F23: Mercedes-Benz Media: „peste 13 000 rot/min” la v_max (spate), peste 15 000 rot/min (față)
A24: i_g | B24: Raportul total de transmitere i_g (punte spate, estimat) | C24: =n_m_vmax/(v_max/3.6/(2*PI()*r_w)*60) -> 5.6285679 | D24: – | E24: calculat | F24: Raportul nu este publicat: i_g = n_motor / n_roată la v_max (limită inferioară). Se folosește ca raport echivalent pentru întreaga acționare.
A25: eta_t | B25: Randamentul transmisiei η (motor → roată) | C25: 0.95 | D25: – | E25: ipoteză | F25: Reductor planetar cu o treaptă (~0,97) × pierderi în arbori/lagăre; valoare uzuală 0,93–0,97
A26: delta_m | B26: Coeficientul maselor în rotație δ | C26: 1 | D26: – | E26: curs C1 | F26: Curs C1, rel. (23): pentru modelul inițial F_i = M·a este suficient (δ = 1)
A27: Mediu și drum
A28: g_acc | B28: Accelerația gravitațională g | C28: 9.81 | D28: m/s² | E28: constantă | F28: –
A29: rho_aer | B29: Densitatea aerului ρ | C29: 1.225 | D29: kg/m³ | E29: ipoteză | F29: Atmosfera standard: 15 °C, 101,325 kPa, fără vânt (rel. 7)
A30: f_r | B30: Coeficientul de rezistență la rulare f | C30: 0.012 | D30: – | E30: curs C1 | F30: Curs C1, tabel: asfalt uscat, normal – 0,012 (interval 0,010–0,015)
A31: mu_us | B31: Coeficientul de aderență μ – asfalt uscat | C31: 0.85 | D31: – | E31: curs C1 | F31: Curs C1, tabel: asfalt uscat 0,80–0,90 (mijlocul intervalului)
A32: mu_perf | B32: Coeficientul de aderență μ – anvelope de performanță | C32: 1.2 | D32: – | E32: ipoteză | F32: Anvelope sport de înaltă aderență pe asfalt uscat, cald (verificare a performanței oficiale)
A33: Cerințe de calcul (regimuri)
A34: v_acc | B34: Viteza de capăt a accelerării | C34: 100 | D34: km/h | E34: oficial | F34: 0–100 km/h
A35: a_med | B35: Accelerația medie impusă 0–100 km/h | C35: =v_acc/3.6/t_acc -> 11.574074 | D35: m/s² | E35: calculat | F35: a = Δv / t
A36: p_1 | B36: Pantă de verificare (regim S3) | C36: 10 | D36: % | E36: curs C1 | F36: Curs C1, exemplul rel. (21): pantă de 10 %
A37: v_p1 | B37: Viteza constantă pe panta p_1 | C37: 100 | D37: km/h | E37: ipoteză | F37: Deplasare pe autostradă în rampă
A38: p_max | B38: Panta maximă pentru pornire (regim S4) | C38: 30 | D38: % | E38: ipoteză | F38: Cerință uzuală pentru autoturisme (rampe de parcare); se precizează în tema de proiectare
A40: Ipoteze ale modelului (curs C1, cap. 1):
A41: 1. Model longitudinal simplificat: vehiculul este un corp rigid care se deplasează pe direcția pantei; vânt nul (rel. 7, nu rel. 8).
A42: 2. Tracțiune integrală (3 motoare, 2 spate + 1 față): întreaga greutate este pe roți motoare, deci F_z = M·g·cos α (rel. 37), fără transfer de sarcină între punți.
...

Sheet Calcul regimuri
A1: Calculul regimurilor caracteristice – relațiile din curs C1
A2: Fiecare coloană este un regim de funcționare. Rândurile urmează succesiunea din curs: rezistențe → forța de tracțiune necesară → cuplu și putere → verificarea aderenței și a acționării.
A4: Rel. curs | B4: Mărime | C4: Expresie | D4: Unitate | E4: S1 | F4: S2a | G4: S2b | H4: S3 | I4: S4
B5: Regim | E5: Viteză maximă, drum orizontal | F5: Accelerare 0–100 km/h – la pornire (v = 0) | G5: Accelerare 0–100 km/h – la 100 km/h | H5: Rampă 10 % la 100 km/h, viteză constantă | I5: Pornire pe panta maximă 30 % (v ≈ 0, a = 0)
B6: Viteza v | C6: intrare | D6: km/h | E6: =v_max -> 300 | F6: 0 | G6: =v_acc -> 100 | H6: =v_p1 -> 100 | I6: 0
B7: Viteza v | C7: v / 3,6 | D7: m/s | E7: =E6/3.6 -> 83.333333 | F7: =F6/3.6 -> 0 | G7: =G6/3.6 -> 27.777778 | H7: =H6/3.6 -> 27.777778 | I7: =I6/3.6 -> 0
B8: Panta p = tg α | C8: intrare | D8: % | E8: 0 | F8: 0 | G8: 0 | H8: =p_1 -> 10 | I8: =p_max -> 30
A9: (18) | B9: Unghiul pantei α | C9: arctg(p/100) | D9: ° | E9: =DEGREES(ATAN(E8/100)) -> 0 | F9: =DEGREES(ATAN(F8/100)) -> 0 | G9: =DEGREES(ATAN(G8/100)) -> 0 | H9: =DEGREES(ATAN(H8/100)) -> 5.7105931 | I9: =DEGREES(ATAN(I8/100)) -> 16.699244
B10: Accelerația a | C10: intrare | D10: m/s² | E10: 0 | F10: =a_med -> 11.574074 | G10: =a_med -> 11.574074 | H10: 0 | I10: 0
A11: (7) | B11: Rezistența aerodinamică F_ra | C11: ½·ρ·Cx·S·v² | D11: N | E11: =0.5*rho_aer*C_x*A_f*E7^2 -> 2283.2639 | F11: =0.5*rho_aer*C_x*A_f*F7^2 -> 0 | G11: =0.5*rho_aer*C_x*A_f*G7^2 -> 253.69599 | H11: =0.5*rho_aer*C_x*A_f*H7^2 -> 253.69599 | I11: =0.5*rho_aer*C_x*A_f*I7^2 -> 0
A12: (14) | B12: Rezistența la rulare F_f | C12: f·M·g·cos α | D12: N | E12: =f_r*M_calc*g_acc*COS(RADIANS(E9)) -> 298.4202 | F12: =f_r*M_calc*g_acc*COS(RADIANS(F9)) -> 298.4202 | G12: =f_r*M_calc*g_acc*COS(RADIANS(G9)) -> 298.4202 | H12: =f_r*M_calc*g_acc*COS(RADIANS(H9)) -> 296.9392 | I12: =f_r*M_calc*g_acc*COS(RADIANS(I9)) -> 285.83471
A13: (17) | B13: Rezistența la pantă G_t | C13: M·g·sin α | D13: N | E13: =M_calc*g_acc*SIN(RADIANS(E9)) -> 0 | F13: =M_calc*g_acc*SIN(RADIANS(F9)) -> 0 | G13: =M_calc*g_acc*SIN(RADIANS(G9)) -> 0 | H13: =M_calc*g_acc*SIN(RADIANS(H9)) -> 2474.4933 | I13: =M_calc*g_acc*SIN(RADIANS(I9)) -> 7145.8678
A14: (22)/(23) | B14: Forța de inerție F_i | C14: δ·M·a | D14: N | E14: =delta_m*M_calc*E10 -> 0 | F14: =delta_m*M_calc*F10 -> 29340.278 | G14: =delta_m*M_calc*G10 -> 29340.278 | H14: =delta_m*M_calc*H10 -> 0 | I14: =delta_m*M_calc*I10 -> 0
A15: (25)/(26) | B15: Forța de tracțiune necesară F_t | C15: F_ra + F_f + G_t + M·a | D15: N | E15: =SUM(E11:E14) -> 2581.6841 | F15: =SUM(F11:F14) -> 29638.698 | G15: =SUM(G11:G14) -> 29892.394 | H15: =SUM(H11:H14) -> 3025.1285 | I15: =SUM(I11:I14) -> 7431.7025
A16: (31)/(46) | B16: Cuplul la roți T_w | C16: F_t·r_w | D16: N·m | E16: =E15*r_w -> 889.50376 | F16: =F15*r_w -> 10211.836 | G16: =G15*r_w -> 10299.245 | H16: =H15*r_w -> 1042.2899 | I16: =I15*r_w -> 2560.5485
A17: (28)/(47) | B17: Puterea la roți P_w | C17: F_t·v | D17: kW | E17: =E15*E7/1000 -> 215.14034 | F17: =F15*F7/1000 -> 0 | G17: =G15*G7/1000 -> 830.34428 | H17: =H15*H7/1000 -> 84.031347 | I17: =I15*I7/1000 -> 0
A18: (29)/(30) | B18: Puterea cerută motoarelor P_m | C18: P_w / η | D18: kW | E18: =E17/eta_t -> 226.46352 | F18: =F17/eta_t -> 0 | G18: =G17/eta_t -> 874.04661 | H18: =H17/eta_t -> 88.45405 | I18: =I17/eta_t -> 0
A19: (33) | B19: Cuplul cerut motoarelor T_m | C19: F_t·r_w / (i_g·η) | D19: N·m | E19: =E15*r_w/(i_g*eta_t) -> 166.35133 | F19: =F15*r_w/(i_g*eta_t) -> 1909.7754 | G19: =G15*r_w/(i_g*eta_t) -> 1926.1224 | H19: =H15*r_w/(i_g*eta_t) -> 194.92476 | I19: =I15*r_w/(i_g*eta_t) -> 478.86323
B20: Turația roții n_w | C20: v / (2π·r_w) · 60 | D20: rot/min | E20: =E7/(2*PI()*r_w)*60 -> 2309.6461 | F20: =F7/(2*PI()*r_w)*60 -> 0 | G20: =G7/(2*PI()*r_w)*60 -> 769.88204 | H20: =H7/(2*PI()*r_w)*60 -> 769.88204 | I20: =I7/(2*PI()*r_w)*60 -> 0
B21: Turația motoarelor n_m | C21: n_w · i_g | D21: rot/min | E21: =E20*i_g -> 13000 | F21: =F20*i_g -> 0 | G21: =G20*i_g -> 4333.3333 | H21: =H20*i_g -> 4333.3333 | I21: =I20*i_g -> 0
A22: (37) | B22: Sarcina normală pe roți F_z | C22: M·g·cos α | D22: N | E22: =M_calc*g_acc*COS(RADIANS(E9)) -> 24868.35 | F22: =M_calc*g_acc*COS(RADIANS(F9)) -> 24868.35 | G22: =M_calc*g_acc*COS(RADIANS(G9)) -> 24868.35 | H22: =M_calc*g_acc*COS(RADIANS(H9)) -> 24744.933 | I22: =M_calc*g_acc*COS(RADIANS(I9)) -> 23819.559
A23: (35) | B23: Forța maximă transmisibilă prin aderență μ·F_z | C23: μ·F_z (μ = 0,85) | D23: N | E23: =mu_us*E22 -> 21138.097 | F23: =mu_us*F22 -> 21138.097 | G23: =mu_us*G22 -> 21138.097 | H23: =mu_us*H22 -> 21033.193 | I23: =mu_us*I22 -> 20246.625
A24: (36) | B24: Coeficient de aderență necesar μ_nec | C24: F_t / F_z | D24: – | E24: =E15/E22 -> 0.10381405 | F24: =F15/F22 -> 1.1918241 | G24: =G15/G22 -> 1.2020256 | H24: =H15/H22 -> 0.12225244 | I24: =I15/I22 -> 0.312
A25: (36)/(41) | B25: Verificare aderență F_t ≤ μ·F_z | E25: =IF(E15<=E23,"DA","NU – patinare") -> DA | F25: =IF(F15<=F23,"DA","NU – patinare") -> NU – patinare | G25: =IF(G15<=G23,"DA","NU – patinare") -> NU – patinare | H25: =IF(H15<=H23,"DA","NU – patinare") -> DA | I25: =IF(I15<=I23,"DA","NU – patinare") -> DA
A26: (40) | B26: Forța maximă a acționării F_t,drive | C26: min(T_m,max·i_g·η/r_w ; η·P_vârf/v) | D26: N | E26: =IF(E7=0,T_max*i_g*eta_t/r_w,MIN(T_max*i_g*eta_t/r_w,eta_t*P_vf*1000/E7)) -> 9804 | F26: =IF(F7=0,T_max*i_g*eta_t/r_w,MIN(T_max*i_g*eta_t/r_w,eta_t*P_vf*1000/F7)) -> 31038.935 | G26: =IF(G7=0,T_max*i_g*eta_t/r_w,MIN(T_max*i_g*eta_t/r_w,eta_t*P_vf*1000/G7)) -> 29412 | H26: =IF(H7=0,T_max*i_g*eta_t/r_w,MIN(T_max*i_g*eta_t/r_w,eta_t*P_vf*1000/H7)) -> 29412 | I26: =IF(I7=0,T_max*i_g*eta_t/r_w,MIN(T_max*i_g*eta_t/r_w,eta_t*P_vf*1000/I7)) -> 31038.935
A27: (42) | B27: Forța de tracțiune maximă realizabilă F_t,max | C27: min(F_t,drive ; μ·F_z) | D27: N | E27: =MIN(E26,E23) -> 9804 | F27: =MIN(F26,F23) -> 21138.097 | G27: =MIN(G26,G23) -> 21138.097 | H27: =MIN(H26,H23) -> 21033.193 | I27: =MIN(I26,I23) -> 20246.625
B28: Limitarea dominantă | E28: =IF(E26<=E23,"acționare","aderență") -> acționare | F28: =IF(F26<=F23,"acționare","aderență") -> aderență | G28: =IF(G26<=G23,"acționare","aderență") -> aderență | H28: =IF(H26<=H23,"acționare","aderență") -> aderență | I28: =IF(I26<=I23,"acționare","aderență") -> aderență
A29: (43) | B29: Condiția de realizare F_t,max ≥ F_t | E29: =IF(E27>=E15,"ÎNDEPLINITĂ","NEÎNDEPLINITĂ") -> ÎNDEPLINITĂ | F29: =IF(F27>=F15,"ÎNDEPLINITĂ","NEÎNDEPLINITĂ") -> NEÎNDEPLINITĂ | G29: =IF(G27>=G15,"ÎNDEPLINITĂ","NEÎNDEPLINITĂ") -> NEÎNDEPLINITĂ | H29: =IF(H27>=H15,"ÎNDEPLINITĂ","NEÎNDEPLINITĂ") -> ÎNDEPLINITĂ | I29: =IF(I27>=I15,"ÎNDEPLINITĂ","NEÎNDEPLINITĂ") -> ÎNDEPLINITĂ
B30: Rezerva de forță F_t,max − F_t | D30: N | E30: =E27-E15 -> 7222.3159 | F30: =F27-F15 -> -8500.6005 | G30: =G27-G15 -> -8754.2965 | H30: =H27-H15 -> 18008.065 | I30: =I27-I15 -> 12814.923
B31: Încărcarea față de puterea continuă | C31: P_m / P_cont | D31: % | E31: =E18/P_cont -> 0.42728965 | F31: =F18/P_cont -> 0 | G31: =G18/P_cont -> 1.6491445 | H31: =H18/P_cont -> 0.16689443 | I31: =I18/P_cont -> 0
B32: Încărcarea față de puterea de vârf | C32: P_m / P_vârf | D32: % | E32: =E18/P_vf -> 0.26332967 | F32: =F18/P_vf -> 0 | G32: =G18/P_vf -> 1.0163333 | H32: =H18/P_vf -> 0.10285355 | I32: =I18/P_vf -> 0
A35: Indicatori derivați
A36: Nr. | B36: Mărime | C36: Expresie | D36: Unitate | E36: Valoare
A37: D1 | B37: Accelerația maximă la pornire, limitată de aderență (μ = 0,85) | C37: (μ − f)·g / δ | D37: m/s² | E37: =(mu_us-f_r)*g_acc/delta_m -> 8.22078
A38: D2 | B38: Panta maximă urcată limitată de aderență (μ = 0,85), v ≈ 0 | C38: tg α = μ − f (din μ·cos α ≥ f·cos α + sin α) | D38: % | E38: =(mu_us-f_r)*100 -> 83.8
A39: D3 | B39: Raportul F_t,drive(0) / (M·g) | C39: T_m,max·i_g·η / (r_w·M·g) | D39: – | E39: =T_max*i_g*eta_t/(r_w*M_calc*g_acc) -> 1.2481301
A40: D4 | B40: Panta maximă limitată de acționare | C40: f·cos α + sin α = D3 (nelimitată dacă D3 > √(1+f²)) | D40: % | E40: =IF(E39>SQRT(1+f_r^2),"nelimitată",100*TAN(ASIN(E39/SQRT(1+f_r^2))-ATAN(f_r))) -> nelimitată
A41: D5 | B41: Viteza maximă limitată de puterea continuă (teoretic) | C41: ½ρCxS·v³ + fMg·v = η·P_cont (Cardano) | D41: km/h | E41: =3.6*(POWER((eta_t*P_cont*1000/(0.5*rho_aer*C_x*A_f))/2+SQRT(((eta_t*P_cont*1000/(0.5*rho_aer*C_x*A_f)))^2/4+((f_r*M_calc*g_acc/(0.5*rho_aer*C_x*A_f)))^3/27),1/3)-POWER(SQRT(((eta_t*P_cont*1000/(0.5*rho_aer*C_x*A_f)))^2/4+((f_r*M_calc*g_acc/(0.5*rho_aer*C_x*A_f)))^3/27)-(eta_t*P_cont*1000/(0.5*rho_aer*C_x*A_f))/2,1/3)) -> 405.50276
A42: D6 | B42: Viteza maximă limitată de puterea de vârf (teoretic) | C42: ½ρCxS·v³ + fMg·v = η·P_vârf (Cardano) | D42: km/h | E42: =3.6*(POWER((eta_t*P_vf*1000/(0.5*rho_aer*C_x*A_f))/2+SQRT(((eta_t*P_vf*1000/(0.5*rho_aer*C_x*A_f)))^2/4+((f_r*M_calc*g_acc/(0.5*rho_aer*C_x*A_f)))^3/27),1/3)-POWER(SQRT(((eta_t*P_vf*1000/(0.5*rho_aer*C_x*A_f)))^2/4+((f_r*M_calc*g_acc/(0.5*rho_aer*C_x*A_f)))^3/27)-(eta_t*P_vf*1000/(0.5*rho_aer*C_x*A_f))/2,1/3)) -> 479.56694
A43: D7 | B43: Viteza la care se trece de la limitarea de cuplu la cea de putere (P_vârf) | C43: v_b = η·P_vârf / F_t,drive(0) | D43: km/h | E43: =3.6*eta_t*P_vf*1000/(T_max*i_g*eta_t/r_w) -> 94.758405
...

Sheet Caracteristica tractiune
A1: Caracteristica de tracțiune F(v), puterea P(v) și estimarea accelerării
A2: Pas de 5 km/h. F_t,drive = min(T_m,max·i_g·η/r_w ; η·P/v). F_t,max = min(F_t,drive ; μ·M·g). a = (F_t,max − F_ra − F_f)/(δ·M); timpul se obține prin integrare numerică: Δt = Δv / a_mediu (metoda trapezelor). Curba „continuu” folosește T_m,max la viteze mici, deoarece cuplul continuu nu este publicat.
A4: v [km/h] | B4: v [m/s] | C4: F_ra [N] | D4: F_f [N] | E4: F_rez orizontal [N] | F4: F_rez rampă 10 % [N] | G4: F_t,drive vârf [N] | H4: F_t,drive continuu [N] | I4: μ·M·g (μ=0,85) [N] | J4: μ·M·g (μ=1,20) [N] | K4: F_t,max μ=0,85 [N] | L4: F_t,max μ=1,20 [N] | M4: a μ=0,85 [m/s²] | N4: a μ=1,20 [m/s²] | O4: t μ=0,85 [s] | P4: t μ=1,20 [s] | Q4: P_m orizontal [kW] | R4: P_m rampă 10 % [kW] | S4: P_vârf [kW] | T4: P_cont [kW] | U4: n_m [rot/min]
A5: 0 | B5: =A5/3.6 -> 0 | C5: =0.5*rho_aer*C_x*A_f*B5^2 -> 0 | D5: =f_r*M_calc*g_acc -> 298.4202 | E5: =C5+D5 -> 298.4202 | F5: =C5+M_calc*g_acc*(f_r*COS(ATAN(p_1/100))+SIN(ATAN(p_1/100))) -> 2771.4325 | G5: =IF(B5=0,T_max*i_g*eta_t/r_w,MIN(T_max*i_g*eta_t/r_w,eta_t*P_vf*1000/B5)) -> 31038.935 | H5: =IF(B5=0,T_max*i_g*eta_t/r_w,MIN(T_max*i_g*eta_t/r_w,eta_t*P_cont*1000/B5)) -> 31038.935 | I5: =mu_us*M_calc*g_acc -> 21138.097 | J5: =mu_perf*M_calc*g_acc -> 29842.02 | K5: =MIN(G5,I5) -> 21138.097 | L5: =MIN(G5,J5) -> 29842.02 | M5: =(K5-E5)/(delta_m*M_calc) -> 8.22078 | N5: =(L5-E5)/(delta_m*M_calc) -> 11.65428 | O5: 0 | P5: 0 | Q5: =E5*B5/eta_t/1000 -> 0 | R5: =F5*B5/eta_t/1000 -> 0 | S5: =P_vf -> 860 | T5: =P_cont -> 530 | U5: =B5/(2*PI()*r_w)*60*i_g -> 0
A6: 5 | B6: =A6/3.6 -> 1.3888889 | C6: =0.5*rho_aer*C_x*A_f*B6^2 -> 0.63423997 | D6: =f_r*M_calc*g_acc -> 298.4202 | E6: =C6+D6 -> 299.05444 | F6: =C6+M_calc*g_acc*(f_r*COS(ATAN(p_1/100))+SIN(ATAN(p_1/100))) -> 2772.0667 | G6: =IF(B6=0,T_max*i_g*eta_t/r_w,MIN(T_max*i_g*eta_t/r_w,eta_t*P_vf*1000/B6)) -> 31038.935 | H6: =IF(B6=0,T_max*i_g*eta_t/r_w,MIN(T_max*i_g*eta_t/r_w,eta_t*P_cont*1000/B6)) -> 31038.935 | I6: =mu_us*M_calc*g_acc -> 21138.097 | J6: =mu_perf*M_calc*g_acc -> 29842.02 | K6: =MIN(G6,I6) -> 21138.097 | L6: =MIN(G6,J6) -> 29842.02 | M6: =(K6-E6)/(delta_m*M_calc) -> 8.2205298 | N6: =(L6-E6)/(delta_m*M_calc) -> 11.65403 | O6: =O5+(B6-B5)/((M6+M5)/2) -> 0.16895112 | P6: =P5+(B6-B5)/((N6+N5)/2) -> 0.11917543 | Q6: =E6*B6/eta_t/1000 -> 0.43721409 | R6: =F6*B6/eta_t/1000 -> 4.0527292 | S6: =P_vf -> 860 | T6: =P_cont -> 530 | U6: =B6/(2*PI()*r_w)*60*i_g -> 216.66667
A7: 10 | B7: =A7/3.6 -> 2.7777778 | C7: =0.5*rho_aer*C_x*A_f*B7^2 -> 2.5369599 | D7: =f_r*M_calc*g_acc -> 298.4202 | E7: =C7+D7 -> 300.95716 | F7: =C7+M_calc*g_acc*(f_r*COS(ATAN(p_1/100))+SIN(ATAN(p_1/100))) -> 2773.9695 | G7: =IF(B7=0,T_max*i_g*eta_t/r_w,MIN(T_max*i_g*eta_t/r_w,eta_t*P_vf*1000/B7)) -> 31038.935 | H7: =IF(B7=0,T_max*i_g*eta_t/r_w,MIN(T_max*i_g*eta_t/r_w,eta_t*P_cont*1000/B7)) -> 31038.935 | I7: =mu_us*M_calc*g_acc -> 21138.097 | J7: =mu_perf*M_calc*g_acc -> 29842.02 | K7: =MIN(G7,I7) -> 21138.097 | L7: =MIN(G7,J7) -> 29842.02 | M7: =(K7-E7)/(delta_m*M_calc) -> 8.2197792 | N7: =(L7-E7)/(delta_m*M_calc) -> 11.653279 | O7: =O6+(B7-B6)/((M7+M6)/2) -> 0.33791253 | P7: =P6+(B7-B6)/((N7+N6)/2) -> 0.23835597 | Q7: =E7*B7/eta_t/1000 -> 0.8799917 | R7: =F7*B7/eta_t/1000 -> 8.1110218 | S7: =P_vf -> 860 | T7: =P_cont -> 530 | U7: =B7/(2*PI()*r_w)*60*i_g -> 433.33333
A8: 15 | B8: =A8/3.6 -> 4.1666667 | C8: =0.5*rho_aer*C_x*A_f*B8^2 -> 5.7081597 | D8: =f_r*M_calc*g_acc -> 298.4202 | E8: =C8+D8 -> 304.12836 | F8: =C8+M_calc*g_acc*(f_r*COS(ATAN(p_1/100))+SIN(ATAN(p_1/100))) -> 2777.1407 | G8: =IF(B8=0,T_max*i_g*eta_t/r_w,MIN(T_max*i_g*eta_t/r_w,eta_t*P_vf*1000/B8)) -> 31038.935 | H8: =IF(B8=0,T_max*i_g*eta_t/r_w,MIN(T_max*i_g*eta_t/r_w,eta_t*P_cont*1000/B8)) -> 31038.935 | I8: =mu_us*M_calc*g_acc -> 21138.097 | J8: =mu_perf*M_calc*g_acc -> 29842.02 | K8: =MIN(G8,I8) -> 21138.097 | L8: =MIN(G8,J8) -> 29842.02 | M8: =(K8-E8)/(delta_m*M_calc) -> 8.2185283 | N8: =(L8-E8)/(delta_m*M_calc) -> 11.652028 | O8: =O7+(B8-B7)/((M8+M7)/2) -> 0.50689452 | P8: =P7+(B8-B7)/((N8+N7)/2) -> 0.35754675 | Q8: =E8*B8/eta_t/1000 -> 1.3338963 | R8: =F8*B8/eta_t/1000 -> 12.180442 | S8: =P_vf -> 860 | T8: =P_cont -> 530 | U8: =B8/(2*PI()*r_w)*60*i_g -> 650
A9: 20 | B9: =A9/3.6 -> 5.5555556 | C9: =0.5*rho_aer*C_x*A_f*B9^2 -> 10.14784 | D9: =f_r*M_calc*g_acc -> 298.4202 | E9: =C9+D9 -> 308.56804 | F9: =C9+M_calc*g_acc*(f_r*COS(ATAN(p_1/100))+SIN(ATAN(p_1/100))) -> 2781.5803 | G9: =IF(B9=0,T_max*i_g*eta_t/r_w,MIN(T_max*i_g*eta_t/r_w,eta_t*P_vf*1000/B9)) -> 31038.935 | H9: =IF(B9=0,T_max*i_g*eta_t/r_w,MIN(T_max*i_g*eta_t/r_w,eta_t*P_cont*1000/B9)) -> 31038.935 | I9: =mu_us*M_calc*g_acc -> 21138.097 | J9: =mu_perf*M_calc*g_acc -> 29842.02 | K9: =MIN(G9,I9) -> 21138.097 | L9: =MIN(G9,J9) -> 29842.02 | M9: =(K9-E9)/(delta_m*M_calc) -> 8.2167769 | N9: =(L9-E9)/(delta_m*M_calc) -> 11.650277 | O9: =O8+(B9-B8)/((M9+M8)/2) -> 0.67590737 | P9: =P8+(B9-B8)/((N9+N8)/2) -> 0.47675289 | Q9: =E9*B9/eta_t/1000 -> 1.8044915 | R9: =F9*B9/eta_t/1000 -> 16.266552 | S9: =P_vf -> 860 | T9: =P_cont -> 530 | U9: =B9/(2*PI()*r_w)*60*i_g -> 866.66667
A10: 25 | B10: =A10/3.6 -> 6.9444444 | C10: =0.5*rho_aer*C_x*A_f*B10^2 -> 15.855999 | D10: =f_r*M_calc*g_acc -> 298.4202 | E10: =C10+D10 -> 314.2762 | F10: =C10+M_calc*g_acc*(f_r*COS(ATAN(p_1/100))+SIN(ATAN(p_1/100))) -> 2787.2885 | G10: =IF(B10=0,T_max*i_g*eta_t/r_w,MIN(T_max*i_g*eta_t/r_w,eta_t*P_vf*1000/B10)) -> 31038.935 | H10: =IF(B10=0,T_max*i_g*eta_t/r_w,MIN(T_max*i_g*eta_t/r_w,eta_t*P_cont*1000/B10)) -> 31038.935 | I10: =mu_us*M_calc*g_acc -> 21138.097 | J10: =mu_perf*M_calc*g_acc -> 29842.02 | K10: =MIN(G10,I10) -> 21138.097 | L10: =MIN(G10,J10) -> 29842.02 | M10: =(K10-E10)/(delta_m*M_calc) -> 8.2145252 | N10: =(L10-E10)/(delta_m*M_calc) -> 11.648025 | O10: =O9+(B10-B9)/((M10+M9)/2) -> 0.84496139 | P10: =P9+(B10-B9)/((N10+N9)/2) -> 0.59597951 | Q10: =E10*B10/eta_t/1000 -> 2.2973406 | R10: =F10*B10/eta_t/1000 -> 20.374916 | S10: =P_vf -> 860 | T10: =P_cont -> 530 | U10: =B10/(2*PI()*r_w)*60*i_g -> 1083.3333
A11: 30 | B11: =A11/3.6 -> 8.3333333 | C11: =0.5*rho_aer*C_x*A_f*B11^2 -> 22.832639 | D11: =f_r*M_calc*g_acc -> 298.4202 | E11: =C11+D11 -> 321.25284 | F11: =C11+M_calc*g_acc*(f_r*COS(ATAN(p_1/100))+SIN(ATAN(p_1/100))) -> 2794.2651 | G11: =IF(B11=0,T_max*i_g*eta_t/r_w,MIN(T_max*i_g*eta_t/r_w,eta_t*P_vf*1000/B11)) -> 31038.935 | H11: =IF(B11=0,T_max*i_g*eta_t/r_w,MIN(T_max*i_g*eta_t/r_w,eta_t*P_cont*1000/B11)) -> 31038.935 | I11: =mu_us*M_calc*g_acc -> 21138.097 | J11: =mu_perf*M_calc*g_acc -> 29842.02 | K11: =MIN(G11,I11) -> 21138.097 | L11: =MIN(G11,J11) -> 29842.02 | M11: =(K11-E11)/(delta_m*M_calc) -> 8.211773 | N11: =(L11-E11)/(delta_m*M_calc) -> 11.645273 | O11: =O10+(B11-B10)/((M11+M10)/2) -> 1.0140669 | P11: =P10+(B11-B10)/((N11+N10)/2) -> 0.71523174 | Q11: =E11*B11/eta_t/1000 -> 2.8180074 | R11: =F11*B11/eta_t/1000 -> 24.511098 | S11: =P_vf -> 860 | T11: =P_cont -> 530 | U11: =B11/(2*PI()*r_w)*60*i_g -> 1300
A12: 35 | B12: =A12/3.6 -> 9.7222222 | C12: =0.5*rho_aer*C_x*A_f*B12^2 -> 31.077758 | D12: =f_r*M_calc*g_acc -> 298.4202 | E12: =C12+D12 -> 329.49796 | F12: =C12+M_calc*g_acc*(f_r*COS(ATAN(p_1/100))+SIN(ATAN(p_1/100))) -> 2802.5103 | G12: =IF(B12=0,T_max*i_g*eta_t/r_w,MIN(T_max*i_g*eta_t/r_w,eta_t*P_vf*1000/B12)) -> 31038.935 | H12: =IF(B12=0,T_max*i_g*eta_t/r_w,MIN(T_max*i_g*eta_t/r_w,eta_t*P_cont*1000/B12)) -> 31038.935 | I12: =mu_us*M_calc*g_acc -> 21138.097 | J12: =mu_perf*M_calc*g_acc -> 29842.02 | K12: =MIN(G12,I12) -> 21138.097 | L12: =MIN(G12,J12) -> 29842.02 | M12: =(K12-E12)/(delta_m*M_calc) -> 8.2085205 | N12: =(L12-E12)/(delta_m*M_calc) -> 11.642021 | O12: =O11+(B12-B11)/((M12+M11)/2) -> 1.1832343 | P12: =P11+(B12-B11)/((N12+N11)/2) -> 0.83451472 | Q12: =E12*B12/eta_t/1000 -> 3.3720551 | R12: =F12*B12/eta_t/1000 -> 28.680661 | S12: =P_vf -> 860 | T12: =P_cont -> 530 | U12: =B12/(2*PI()*r_w)*60*i_g -> 1516.6667
A13: 40 | B13: =A13/3.6 -> 11.111111 | C13: =0.5*rho_aer*C_x*A_f*B13^2 -> 40.591358 | D13: =f_r*M_calc*g_acc -> 298.4202 | E13: =C13+D13 -> 339.01156 | F13: =C13+M_calc*g_acc*(f_r*COS(ATAN(p_1/100))+SIN(ATAN(p_1/100))) -> 2812.0239 | G13: =IF(B13=0,T_max*i_g*eta_t/r_w,MIN(T_max*i_g*eta_t/r_w,eta_t*P_vf*1000/B13)) -> 31038.935 | H13: =IF(B13=0,T_max*i_g*eta_t/r_w,MIN(T_max*i_g*eta_t/r_w,eta_t*P_cont*1000/B13)) -> 31038.935 | I13: =mu_us*M_calc*g_acc -> 21138.097 | J13: =mu_perf*M_calc*g_acc -> 29842.02 | K13: =MIN(G13,I13) -> 21138.097 | L13: =MIN(G13,J13) -> 29842.02 | M13: =(K13-E13)/(delta_m*M_calc) -> 8.2047676 | N13: =(L13-E13)/(delta_m*M_calc) -> 11.638268 | O13: =O12+(B13-B12)/((M13+M12)/2) -> 1.3524738 | P13: =P12+(B13-B12)/((N13+N12)/2) -> 0.95383359 | Q13: =E13*B13/eta_t/1000 -> 3.9650475 | R13: =F13*B13/eta_t/1000 -> 32.889168 | S13: =P_vf -> 860 | T13: =P_cont -> 530 | U13: =B13/(2*PI()*r_w)*60*i_g -> 1733.3333
A14: 45 | B14: =A14/3.6 -> 12.5 | C14: =0.5*rho_aer*C_x*A_f*B14^2 -> 51.373438 | D14: =f_r*M_calc*g_acc -> 298.4202 | E14: =C14+D14 -> 349.79364 | F14: =C14+M_calc*g_acc*(f_r*COS(ATAN(p_1/100))+SIN(ATAN(p_1/100))) -> 2822.8059 | G14: =IF(B14=0,T_max*i_g*eta_t/r_w,MIN(T_max*i_g*eta_t/r_w,eta_t*P_vf*1000/B14)) -> 31038.935 | H14: =IF(B14=0,T_max*i_g*eta_t/r_w,MIN(T_max*i_g*eta_t/r_w,eta_t*P_cont*1000/B14)) -> 31038.935 | I14: =mu_us*M_calc*g_acc -> 21138.097 | J14: =mu_perf*M_calc*g_acc -> 29842.02 | K14: =MIN(G14,I14) -> 21138.097 | L14: =MIN(G14,J14) -> 29842.02 | M14: =(K14-E14)/(delta_m*M_calc) -> 8.2005143 | N14: =(L14-E14)/(delta_m*M_calc) -> 11.634014 | O14: =O13+(B14-B13)/((M14+M13)/2) -> 1.521796 | P14: =P13+(B14-B13)/((N14+N13)/2) -> 1.0731935 | Q14: =E14*B14/eta_t/1000 -> 4.6025479 | R14: =F14*B14/eta_t/1000 -> 37.142183 | S14: =P_vf -> 860 | T14: =P_cont -> 530 | U14: =B14/(2*PI()*r_w)*60*i_g -> 1950
A15: 50 | B15: =A15/3.6 -> 13.888889 | C15: =0.5*rho_aer*C_x*A_f*B15^2 -> 63.423997 | D15: =f_r*M_calc*g_acc -> 298.4202 | E15: =C15+D15 -> 361.8442 | F15: =C15+M_calc*g_acc*(f_r*COS(ATAN(p_1/100))+SIN(ATAN(p_1/100))) -> 2834.8565 | G15: =IF(B15=0,T_max*i_g*eta_t/r_w,MIN(T_max*i_g*eta_t/r_w,eta_t*P_vf*1000/B15)) -> 31038.935 | H15: =IF(B15=0,T_max*i_g*eta_t/r_w,MIN(T_max*i_g*eta_t/r_w,eta_t*P_cont*1000/B15)) -> 31038.935 | I15: =mu_us*M_calc*g_acc -> 21138.097 | J15: =mu_perf*M_calc*g_acc -> 29842.02 | K15: =MIN(G15,I15) -> 21138.097 | L15: =MIN(G15,J15) -> 29842.02 | M15: =(K15-E15)/(delta_m*M_calc) -> 8.1957607 | N15: =(L15-E15)/(delta_m*M_calc) -> 11.629261 | O15: =O14+(B15-B14)/((M15+M14)/2) -> 1.6912112 | P15: =P14+(B15-B14)/((N15+N14)/2) -> 1.1925997 | Q15: =E15*B15/eta_t/1000 -> 5.2901198 | R15: =F15*B15/eta_t/1000 -> 41.445271 | S15: =P_vf -> 860 | T15: =P_cont -> 530 | U15: =B15/(2*PI()*r_w)*60*i_g -> 2166.6667
A16: 55 | B16: =A16/3.6 -> 15.277778 | C16: =0.5*rho_aer*C_x*A_f*B16^2 -> 76.743036 | D16: =f_r*M_calc*g_acc -> 298.4202 | E16: =C16+D16 -> 375.16324 | F16: =C16+M_calc*g_acc*(f_r*COS(ATAN(p_1/100))+SIN(ATAN(p_1/100))) -> 2848.1755 | G16: =IF(B16=0,T_max*i_g*eta_t/r_w,MIN(T_max*i_g*eta_t/r_w,eta_t*P_vf*1000/B16)) -> 31038.935 | H16: =IF(B16=0,T_max*i_g*eta_t/r_w,MIN(T_max*i_g*eta_t/r_w,eta_t*P_cont*1000/B16)) -> 31038.935 | I16: =mu_us*M_calc*g_acc -> 21138.097 | J16: =mu_perf*M_calc*g_acc -> 29842.02 | K16: =MIN(G16,I16) -> 21138.097 | L16: =MIN(G16,J16) -> 29842.02 | M16: =(K16-E16)/(delta_m*M_calc) -> 8.1905066 | N16: =(L16-E16)/(delta_m*M_calc) -> 11.624007 | O16: =O15+(B16-B15)/((M16+M15)/2) -> 1.8607298 | P16: =P15+(B16-B15)/((N16+N15)/2) -> 1.3120572 | Q16: =E16*B16/eta_t/1000 -> 6.0333269 | R16: =F16*B16/eta_t/1000 -> 45.803993 | S16: =P_vf -> 860 | T16: =P_cont -> 530 | U16: =B16/(2*PI()*r_w)*60*i_g -> 2383.3333
A17: 60 | B17: =A17/3.6 -> 16.666667 | C17: =0.5*rho_aer*C_x*A_f*B17^2 -> 91.330556 | D17: =f_r*M_calc*g_acc -> 298.4202 | E17: =C17+D17 -> 389.75076 | F17: =C17+M_calc*g_acc*(f_r*COS(ATAN(p_1/100))+SIN(ATAN(p_1/100))) -> 2862.7631 | G17: =IF(B17=0,T_max*i_g*eta_t/r_w,MIN(T_max*i_g*eta_t/r_w,eta_t*P_vf*1000/B17)) -> 31038.935 | H17: =IF(B17=0,T_max*i_g*eta_t/r_w,MIN(T_max*i_g*eta_t/r_w,eta_t*P_cont*1000/B17)) -> 30210 | I17: =mu_us*M_calc*g_acc -> 21138.097 | J17: =mu_perf*M_calc*g_acc -> 29842.02 | K17: =MIN(G17,I17) -> 21138.097 | L17: =MIN(G17,J17) -> 29842.02 | M17: =(K17-E17)/(delta_m*M_calc) -> 8.1847522 | N17: =(L17-E17)/(delta_m*M_calc) -> 11.618252 | O17: =O16+(B17-B16)/((M17+M16)/2) -> 2.0303624 | P17: =P16+(B17-B16)/((N17+N16)/2) -> 1.4315713 | Q17: =E17*B17/eta_t/1000 -> 6.8377326 | R17: =F17*B17/eta_t/1000 -> 50.223913 | S17: =P_vf -> 860 | T17: =P_cont -> 530 | U17: =B17/(2*PI()*r_w)*60*i_g -> 2600
... A65: 300 | B65: =A65/3.6 -> 83.333333 | C65: =0.5*rho_aer*C_x*A_f*B65^2 -> 2283.2639 | D65: =f_r*M_calc*g_acc -> 298.4202 | E65: =C65+D65 -> 2581.6841 | F65: =C65+M_calc*g_acc*(f_r*COS(ATAN(p_1/100))+SIN(ATAN(p_1/100))) -> 5054.6964 | G65: =IF(B65=0,T_max*i_g*eta_t/r_w,MIN(T_max*i_g*eta_t/r_w,eta_t*P_vf*1000/B65)) -> 9804 | H65: =IF(B65=0,T_max*i_g*eta_t/r_w,MIN(T_max*i_g*eta_t/r_w,eta_t*P_cont*1000/B65)) -> 6042 | I65: =mu_us*M_calc*g_acc -> 21138.097 | J65: =mu_perf*M_calc*g_acc -> 29842.02 | K65: =MIN(G65,I65) -> 9804 | L65: =MIN(G65,J65) -> 9804 | M65: =(K65-E65)/(delta_m*M_calc) -> 2.8490398 | N65: =(L65-E65)/(delta_m*M_calc) -> 2.8490398 | O65: =O64+(B65-B64)/((M65+M64)/2) -> 14.62266 | P65: =P64+(B65-B64)/((N65+N64)/2) -> 13.426409 | Q65: =E65*B65/eta_t/1000 -> 226.46352 | R65: =F65*B65/eta_t/1000 -> 443.39442 | S65: =P_vf -> 860 | T65: =P_cont -> 530 | U65: =B65/(2*PI()*r_w)*60*i_g -> 13000
